Workbook

Sheet 2020
B1: NG_P(X≥3) | C1: Actual_P(X≥3) | D1: NG_P(X≥6) | E1: Actual_P(X≥6) | F1: NG_P(X≥9) | G1: Actual_P(X≥9) | H1: NG_P(X≥12) | I1: Actual_P(X≥12) | J1: NG_P(X≥15) | K1: Actual_P(X≥15)
A2: Low_frequency_hour | B2: 3 | C2: 3 | D2: 6 | E2: 6 | F2: 9 | G2: 9 | H2: 12 | I2: 12 | J2: 15 | K2: 15
A3: 0 | B3: =1-_xlfn.BETA.DIST(VLOOKUP($A3,NB_p!$A$2:$G$25,2,FALSE),VLOOKUP($A3,NB_r!$A$2:$G$25,2,FALSE),B$2,TRUE) -> 0.94409791 | C3: =COUNTIF(INDEX($B$33:$Y$242,0,MATCH($A3,$B$32:$Y$32,0)),">="&C$2)/ROWS($A$33:$A$242) -> 0.93809524 | D3: =1-_xlfn.BETA.DIST(VLOOKUP($A3,NB_p!$A$2:$G$25,2,FALSE),VLOOKUP($A3,NB_r!$A$2:$G$25,2,FALSE),D$2,TRUE) -> 0.68189135 | E3: =COUNTIF(INDEX($B$33:$Y$242,0,MATCH($A3,$B$32:$Y$32,0)),">="&E$2)/ROWS($A$33:$A$242) -> 0.68095238 | F3: =1-_xlfn.BETA.DIST(VLOOKUP($A3,NB_p!$A$2:$G$25,2,FALSE),VLOOKUP($A3,NB_r!$A$2:$G$25,2,FALSE),F$2,TRUE) -> 0.34767845 | G3: =COUNTIF(INDEX($B$33:$Y$242,0,MATCH($A3,$B$32:$Y$32,0)),">="&G$2)/ROWS($A$33:$A$242) -> 0.34761905 | H3: =1-_xlfn.BETA.DIST(VLOOKUP($A3,NB_p!$A$2:$G$25,2,FALSE),VLOOKUP($A3,NB_r!$A$2:$G$25,2,FALSE),H$2,TRUE) -> 0.13148672 | I3: =COUNTIF(INDEX($B$33:$Y$242,0,MATCH($A3,$B$32:$Y$32,0)),">="&I$2)/ROWS($A$33:$A$242) -> 0.13333333 | J3: =1-_xlfn.BETA.DIST(VLOOKUP($A3,NB_p!$A$2:$G$25,2,FALSE),VLOOKUP($A3,NB_r!$A$2:$G$25,2,FALSE),J$2,TRUE) -> 0.039395092 | K3: =COUNTIF(INDEX($B$33:$Y$242,0,MATCH($A3,$B$32:$Y$32,0)),">="&K$2)/ROWS($A$33:$A$242) -> 0.023809524
A4: 1 | B4: =1-_xlfn.BETA.DIST(VLOOKUP($A4,NB_p!$A$2:$G$25,2,FALSE),VLOOKUP($A4,NB_r!$A$2:$G$25,2,FALSE),B$2,TRUE) -> 0.9191941 | C4: =COUNTIF(INDEX($B$33:$Y$242,0,MATCH($A4,$B$32:$Y$32,0)),">="&C$2)/ROWS($A$33:$A$242) -> 0.92380952 | D4: =1-_xlfn.BETA.DIST(VLOOKUP($A4,NB_p!$A$2:$G$25,2,FALSE),VLOOKUP($A4,NB_r!$A$2:$G$25,2,FALSE),D$2,TRUE) -> 0.58041071 | E4: =COUNTIF(INDEX($B$33:$Y$242,0,MATCH($A4,$B$32:$Y$32,0)),">="&E$2)/ROWS($A$33:$A$242) -> 0.57619048 | F4: =1-_xlfn.BETA.DIST(VLOOKUP($A4,NB_p!$A$2:$G$25,2,FALSE),VLOOKUP($A4,NB_r!$A$2:$G$25,2,FALSE),F$2,TRUE) -> 0.23139221 | G4: =COUNTIF(INDEX($B$33:$Y$242,0,MATCH($A4,$B$32:$Y$32,0)),">="&G$2)/ROWS($A$33:$A$242) -> 0.23333333 | H4: =1-_xlfn.BETA.DIST(VLOOKUP($A4,NB_p!$A$2:$G$25,2,FALSE),VLOOKUP($A4,NB_r!$A$2:$G$25,2,FALSE),H$2,TRUE) -> 0.063092548 | I4: =COUNTIF(INDEX($B$33:$Y$242,0,MATCH($A4,$B$32:$Y$32,0)),">="&I$2)/ROWS($A$33:$A$242) -> 0.066666667 | J4: =1-_xlfn.BETA.DIST(VLOOKUP($A4,NB_p!$A$2:$G$25,2,FALSE),VLOOKUP($A4,NB_r!$A$2:$G$25,2,FALSE),J$2,TRUE) -> 0.012856111 | K4: =COUNTIF(INDEX($B$33:$Y$242,0,MATCH($A4,$B$32:$Y$32,0)),">="&K$2)/ROWS($A$33:$A$242) -> 0.014285714
A5: 2 | B5: =1-_xlfn.BETA.DIST(VLOOKUP($A5,NB_p!$A$2:$G$25,2,FALSE),VLOOKUP($A5,NB_r!$A$2:$G$25,2,FALSE),B$2,TRUE) -> 0.85439412 | C5: =COUNTIF(INDEX($B$33:$Y$242,0,MATCH($A5,$B$32:$Y$32,0)),">="&C$2)/ROWS($A$33:$A$242) -> 0.85238095 | D5: =1-_xlfn.BETA.DIST(VLOOKUP($A5,NB_p!$A$2:$G$25,2,FALSE),VLOOKUP($A5,NB_r!$A$2:$G$25,2,FALSE),D$2,TRUE) -> 0.45765265 | E5: =COUNTIF(INDEX($B$33:$Y$242,0,MATCH($A5,$B$32:$Y$32,0)),">="&E$2)/ROWS($A$33:$A$242) -> 0.42857143 | F5: =1-_xlfn.BETA.DIST(VLOOKUP($A5,NB_p!$A$2:$G$25,2,FALSE),VLOOKUP($A5,NB_r!$A$2:$G$25,2,FALSE),F$2,TRUE) -> 0.15864017 | G5: =COUNTIF(INDEX($B$33:$Y$242,0,MATCH($A5,$B$32:$Y$32,0)),">="&G$2)/ROWS($A$33:$A$242) -> 0.17142857 | H5: =1-_xlfn.BETA.DIST(VLOOKUP($A5,NB_p!$A$2:$G$25,2,FALSE),VLOOKUP($A5,NB_r!$A$2:$G$25,2,FALSE),H$2,TRUE) -> 0.040054541 | I5: =COUNTIF(INDEX($B$33:$Y$242,0,MATCH($A5,$B$32:$Y$32,0)),">="&I$2)/ROWS($A$33:$A$242) -> 0.047619048 | J5: =1-_xlfn.BETA.DIST(VLOOKUP($A5,NB_p!$A$2:$G$25,2,FALSE),VLOOKUP($A5,NB_r!$A$2:$G$25,2,FALSE),J$2,TRUE) -> 0.0080481483 | K5: =COUNTIF(INDEX($B$33:$Y$242,0,MATCH($A5,$B$32:$Y$32,0)),">="&K$2)/ROWS($A$33:$A$242) -> 0.0095238095
A6: 3 | B6: =1-_xlfn.BETA.DIST(VLOOKUP($A6,NB_p!$A$2:$G$25,2,FALSE),VLOOKUP($A6,NB_r!$A$2:$G$25,2,FALSE),B$2,TRUE) -> 0.81280697 | C6: =COUNTIF(INDEX($B$33:$Y$242,0,MATCH($A6,$B$32:$Y$32,0)),">="&C$2)/ROWS($A$33:$A$242) -> 0.81428571 | D6: =1-_xlfn.BETA.DIST(VLOOKUP($A6,NB_p!$A$2:$G$25,2,FALSE),VLOOKUP($A6,NB_r!$A$2:$G$25,2,FALSE),D$2,TRUE) -> 0.3720676 | E6: =COUNTIF(INDEX($B$33:$Y$242,0,MATCH($A6,$B$32:$Y$32,0)),">="&E$2)/ROWS($A$33:$A$242) -> 0.37619048 | F6: =1-_xlfn.BETA.DIST(VLOOKUP($A6,NB_p!$A$2:$G$25,2,FALSE),VLOOKUP($A6,NB_r!$A$2:$G$25,2,FALSE),F$2,TRUE) -> 0.10272379 | G6: =COUNTIF(INDEX($B$33:$Y$242,0,MATCH($A6,$B$32:$Y$32,0)),">="&G$2)/ROWS($A$33:$A$242) -> 0.12380952 | H6: =1-_xlfn.BETA.DIST(VLOOKUP($A6,NB_p!$A$2:$G$25,2,FALSE),VLOOKUP($A6,NB_r!$A$2:$G$25,2,FALSE),H$2,TRUE) -> 0.019805991 | I6: =COUNTIF(INDEX($B$33:$Y$242,0,MATCH($A6,$B$32:$Y$32,0)),">="&I$2)/ROWS($A$33:$A$242) -> 0.0095238095 | J6: =1-_xlfn.BETA.DIST(VLOOKUP($A6,NB_p!$A$2:$G$25,2,FALSE),VLOOKUP($A6,NB_r!$A$2:$G$25,2,FALSE),J$2,TRUE) -> 0.0029555676 | K6: =COUNTIF(INDEX($B$33:$Y$242,0,MATCH($A6,$B$32:$Y$32,0)),">="&K$2)/ROWS($A$33:$A$242) -> 0.0047619048
A7: 4 | B7: =1-_xlfn.BETA.DIST(VLOOKUP($A7,NB_p!$A$2:$G$25,2,FALSE),VLOOKUP($A7,NB_r!$A$2:$G$25,2,FALSE),B$2,TRUE) -> 0.84490765 | C7: =COUNTIF(INDEX($B$33:$Y$242,0,MATCH($A7,$B$32:$Y$32,0)),">="&C$2)/ROWS($A$33:$A$242) -> 0.84761905 | D7: =1-_xlfn.BETA.DIST(VLOOKUP($A7,NB_p!$A$2:$G$25,2,FALSE),VLOOKUP($A7,NB_r!$A$2:$G$25,2,FALSE),D$2,TRUE) -> 0.43921895 | E7: =COUNTIF(INDEX($B$33:$Y$242,0,MATCH($A7,$B$32:$Y$32,0)),">="&E$2)/ROWS($A$33:$A$242) -> 0.41428571 | F7: =1-_xlfn.BETA.DIST(VLOOKUP($A7,NB_p!$A$2:$G$25,2,FALSE),VLOOKUP($A7,NB_r!$A$2:$G$25,2,FALSE),F$2,TRUE) -> 0.14656567 | G7: =COUNTIF(INDEX($B$33:$Y$242,0,MATCH($A7,$B$32:$Y$32,0)),">="&G$2)/ROWS($A$33:$A$242) -> 0.16666667 | H7: =1-_xlfn.BETA.DIST(VLOOKUP($A7,NB_p!$A$2:$G$25,2,FALSE),VLOOKUP($A7,NB_r!$A$2:$G$25,2,FALSE),H$2,TRUE) -> 0.035522538 | I7: =COUNTIF(INDEX($B$33:$Y$242,0,MATCH($A7,$B$32:$Y$32,0)),">="&I$2)/ROWS($A$33:$A$242) -> 0.038095238 | J7: =1-_xlfn.BETA.DIST(VLOOKUP($A7,NB_p!$A$2:$G$25,2,FALSE),VLOOKUP($A7,NB_r!$A$2:$G$25,2,FALSE),J$2,TRUE) -> 0.0068441648 | K7: =COUNTIF(INDEX($B$33:$Y$242,0,MATCH($A7,$B$32:$Y$32,0)),">="&K$2)/ROWS($A$33:$A$242) -> 0.0095238095
A8: 5 | B8: =1-_xlfn.BETA.DIST(VLOOKUP($A8,NB_p!$A$2:$G$25,2,FALSE),VLOOKUP($A8,NB_r!$A$2:$G$25,2,FALSE),B$2,TRUE) -> 0.90673066 | C8: =COUNTIF(INDEX($B$33:$Y$242,0,MATCH($A8,$B$32:$Y$32,0)),">="&C$2)/ROWS($A$33:$A$242) -> 0.90952381 | D8: =1-_xlfn.BETA.DIST(VLOOKUP($A8,NB_p!$A$2:$G$25,2,FALSE),VLOOKUP($A8,NB_r!$A$2:$G$25,2,FALSE),D$2,TRUE) -> 0.56631009 | E8: =COUNTIF(INDEX($B$33:$Y$242,0,MATCH($A8,$B$32:$Y$32,0)),">="&E$2)/ROWS($A$33:$A$242) -> 0.54285714 | F8: =1-_xlfn.BETA.DIST(VLOOKUP($A8,NB_p!$A$2:$G$25,2,FALSE),VLOOKUP($A8,NB_r!$A$2:$G$25,2,FALSE),F$2,TRUE) -> 0.23388477 | G8: =COUNTIF(INDEX($B$33:$Y$242,0,MATCH($A8,$B$32:$Y$32,0)),">="&G$2)/ROWS($A$33:$A$242) -> 0.20952381 | H8: =1-_xlfn.BETA.DIST(VLOOKUP($A8,NB_p!$A$2:$G$25,2,FALSE),VLOOKUP($A8,NB_r!$A$2:$G$25,2,FALSE),H$2,TRUE) -> 0.069681555 | I8: =COUNTIF(INDEX($B$33:$Y$242,0,MATCH($A8,$B$32:$Y$32,0)),">="&I$2)/ROWS($A$33:$A$242) -> 0.071428571 | J8: =1-_xlfn.BETA.DIST(VLOOKUP($A8,NB_p!$A$2:$G$25,2,FALSE),VLOOKUP($A8,NB_r!$A$2:$G$25,2,FALSE),J$2,TRUE) -> 0.016255632 | K8: =COUNTIF(INDEX($B$33:$Y$242,0,MATCH($A8,$B$32:$Y$32,0)),">="&K$2)/ROWS($A$33:$A$242) -> 0.019047619
A9: 6 | B9: =1-_xlfn.BETA.DIST(VLOOKUP($A9,NB_p!$A$2:$G$25,2,FALSE),VLOOKUP($A9,NB_r!$A$2:$G$25,2,FALSE),B$2,TRUE) -> 0.92250736 | C9: =COUNTIF(INDEX($B$33:$Y$242,0,MATCH($A9,$B$32:$Y$32,0)),">="&C$2)/ROWS($A$33:$A$242) -> 0.95238095 | D9: =1-_xlfn.BETA.DIST(VLOOKUP($A9,NB_p!$A$2:$G$25,2,FALSE),VLOOKUP($A9,NB_r!$A$2:$G$25,2,FALSE),D$2,TRUE) -> 0.68709474 | E9: =COUNTIF(INDEX($B$33:$Y$242,0,MATCH($A9,$B$32:$Y$32,0)),">="&E$2)/ROWS($A$33:$A$242) -> 0.68571429 | F9: =1-_xlfn.BETA.DIST(VLOOKUP($A9,NB_p!$A$2:$G$25,2,FALSE),VLOOKUP($A9,NB_r!$A$2:$G$25,2,FALSE),F$2,TRUE) -> 0.41830156 | G9: =COUNTIF(INDEX($B$33:$Y$242,0,MATCH($A9,$B$32:$Y$32,0)),">="&G$2)/ROWS($A$33:$A$242) -> 0.37619048 | H9: =1-_xlfn.BETA.DIST(VLOOKUP($A9,NB_p!$A$2:$G$25,2,FALSE),VLOOKUP($A9,NB_r!$A$2:$G$25,2,FALSE),H$2,TRUE) -> 0.2186763 | I9: =COUNTIF(INDEX($B$33:$Y$242,0,MATCH($A9,$B$32:$Y$32,0)),">="&I$2)/ROWS($A$33:$A$242) -> 0.19047619 | J9: =1-_xlfn.BETA.DIST(VLOOKUP($A9,NB_p!$A$2:$G$25,2,FALSE),VLOOKUP($A9,NB_r!$A$2:$G$25,2,FALSE),J$2,TRUE) -> 0.10215705 | K9: =COUNTIF(INDEX($B$33:$Y$242,0,MATCH($A9,$B$32:$Y$32,0)),">="&K$2)/ROWS($A$33:$A$242) -> 0.095238095
A10: 23 | B10: =1-_xlfn.BETA.DIST(VLOOKUP($A10,NB_p!$A$2:$G$25,2,FALSE),VLOOKUP($A10,NB_r!$A$2:$G$25,2,FALSE),B$2,TRUE) -> 0.96682926 | C10: =COUNTIF(INDEX($B$33:$Y$242,0,MATCH($A10,$B$32:$Y$32,0)),">="&C$2)/ROWS($A$33:$A$242) -> 0.97142857 | D10: =1-_xlfn.BETA.DIST(VLOOKUP($A10,NB_p!$A$2:$G$25,2,FALSE),VLOOKUP($A10,NB_r!$A$2:$G$25,2,FALSE),D$2,TRUE) -> 0.78091624 | E10: =COUNTIF(INDEX($B$33:$Y$242,0,MATCH($A10,$B$32:$Y$32,0)),">="&E$2)/ROWS($A$33:$A$242) -> 0.82857143 | F10: =1-_xlfn.BETA.DIST(VLOOKUP($A10,NB_p!$A$2:$G$25,2,FALSE),VLOOKUP($A10,NB_r!$A$2:$G$25,2,FALSE),F$2,TRUE) -> 0.48354448 | G10: =COUNTIF(INDEX($B$33:$Y$242,0,MATCH($A10,$B$32:$Y$32,0)),">="&G$2)/ROWS($A$33:$A$242) -> 0.45238095 | H10: =1-_xlfn.BETA.DIST(VLOOKUP($A10,NB_p!$A$2:$G$25,2,FALSE),VLOOKUP($A10,NB_r!$A$2:$G$25,2,FALSE),H$2,TRUE) -> 0.23388285 | I10: =COUNTIF(INDEX($B$33:$Y$242,0,MATCH($A10,$B$32:$Y$32,0)),">="&I$2)/ROWS($A$33:$A$242) -> 0.2047619 | J10: =1-_xlfn.BETA.DIST(VLOOKUP($A10,NB_p!$A$2:$G$25,2,FALSE),VLOOKUP($A10,NB_r!$A$2:$G$25,2,FALSE),J$2,TRUE) -> 0.092548262 | K10: =COUNTIF(INDEX($B$33:$Y$242,0,MATCH($A10,$B$32:$Y$32,0)),">="&K$2)/ROWS($A$33:$A$242) -> 0.076190476
B11: NG_P(X≥5) | C11: Actual_P(X≥5) | D11: NG_P(X≥10) | E11: Actual_P(X≥10) | F11: NG_P(X≥15) | G11: Actual_P(X≥15) | H11: NG_P(X≥20) | I11: Actual_P(X≥20) | J11: NG_P(X≥25) | K11: Actual_P(X≥25) | L11: NG_P(X≥30) | M11: Actual_P(X≥30)
A12: Mid_frequency_hour | B12: 5 | C12: 5 | D12: 10 | E12: 10 | F12: 15 | G12: 15 | H12: 20 | I12: 20 | J12: 25 | K12: 25 | L12: 30 | M12: 30
A13: 7 | B13: =1-_xlfn.BETA.DIST(VLOOKUP($A13,NB_p!$A$2:$G$25,2,FALSE),VLOOKUP($A13,NB_r!$A$2:$G$25,2,FALSE),B$12,TRUE) -> 0.90483955 | C13: =COUNTIF(INDEX($B$33:$Y$242,0,MATCH($A13,$B$32:$Y$32,0)),">="&C$12)/ROWS($A$33:$A$242) -> 0.94761905 | D13: =1-_xlfn.BETA.DIST(VLOOKUP($A13,NB_p!$A$2:$G$25,2,FALSE),VLOOKUP($A13,NB_r!$A$2:$G$25,2,FALSE),D$12,TRUE) -> 0.59815291 | E13: =COUNTIF(INDEX($B$33:$Y$242,0,MATCH($A13,$B$32:$Y$32,0)),">="&E$12)/ROWS($A$33:$A$242) -> 0.6 | F13: =1-_xlfn.BETA.DIST(VLOOKUP($A13,NB_p!$A$2:$G$25,2,FALSE),VLOOKUP($A13,NB_r!$A$2:$G$25,2,FALSE),F$12,TRUE) -> 0.29863876 | G13: =COUNTIF(INDEX($B$33:$Y$242,0,MATCH($A13,$B$32:$Y$32,0)),">="&G$12)/ROWS($A$33:$A$242) -> 0.24761905 | H13: =1-_xlfn.BETA.DIST(VLOOKUP($A13,NB_p!$A$2:$G$25,2,FALSE),VLOOKUP($A13,NB_r!$A$2:$G$25,2,FALSE),H$12,TRUE) -> 0.12250907 | I13: =COUNTIF(INDEX($B$33:$Y$242,0,MATCH($A13,$B$32:$Y$32,0)),">="&I$12)/ROWS($A$33:$A$242) -> 0.10952381 | J13: =1-_xlfn.BETA.DIST(VLOOKUP($A13,NB_p!$A$2:$G$25,2,FALSE),VLOOKUP($A13,NB_r!$A$2:$G$25,2,FALSE),J$12,TRUE) -> 0.043805596 | K13: =COUNTIF(INDEX($B$33:$Y$242,0,MATCH($A13,$B$32:$Y$32,0)),">="&K$12)/ROWS($A$33:$A$242) -> 0.033333333 | L13: =1-_xlfn.BETA.DIST(VLOOKUP($A13,NB_p!$A$2:$G$25,2,FALSE),VLOOKUP($A13,NB_r!$A$2:$G$25,2,FALSE),L$12,TRUE) -> 0.014178069 | M13: =COUNTIF(INDEX($B$33:$Y$242,0,MATCH($A13,$B$32:$Y$32,0)),">="&M$12)/ROWS($A$33:$A$242) -> 0.014285714
A14: 8 | B14: =1-_xlfn.BETA.DIST(VLOOKUP($A14,NB_p!$A$2:$G$25,2,FALSE),VLOOKUP($A14,NB_r!$A$2:$G$25,2,FALSE),B$12,TRUE) -> 0.9731072 | C14: =COUNTIF(INDEX($B$33:$Y$242,0,MATCH($A14,$B$32:$Y$32,0)),">="&C$12)/ROWS($A$33:$A$242) -> 0.9952381 | D14: =1-_xlfn.BETA.DIST(VLOOKUP($A14,NB_p!$A$2:$G$25,2,FALSE),VLOOKUP($A14,NB_r!$A$2:$G$25,2,FALSE),D$12,TRUE) -> 0.79431184 | E14: =COUNTIF(INDEX($B$33:$Y$242,0,MATCH($A14,$B$32:$Y$32,0)),">="&E$12)/ROWS($A$33:$A$242) -> 0.77142857 | F14: =1-_xlfn.BETA.DIST(VLOOKUP($A14,NB_p!$A$2:$G$25,2,FALSE),VLOOKUP($A14,NB_r!$A$2:$G$25,2,FALSE),F$12,TRUE) -> 0.49988185 | G14: =COUNTIF(INDEX($B$33:$Y$242,0,MATCH($A14,$B$32:$Y$32,0)),">="&G$12)/ROWS($A$33:$A$242) -> 0.5 | H14: =1-_xlfn.BETA.DIST(VLOOKUP($A14,NB_p!$A$2:$G$25,2,FALSE),VLOOKUP($A14,NB_r!$A$2:$G$25,2,FALSE),H$12,TRUE) -> 0.24983255 | I14: =COUNTIF(INDEX($B$33:$Y$242,0,MATCH($A14,$B$32:$Y$32,0)),">="&I$12)/ROWS($A$33:$A$242) -> 0.24761905 | J14: =1-_xlfn.BETA.DIST(VLOOKUP($A14,NB_p!$A$2:$G$25,2,FALSE),VLOOKUP($A14,NB_r!$A$2:$G$25,2,FALSE),J$12,TRUE) -> 0.10435864 | K14: =COUNTIF(INDEX($B$33:$Y$242,0,MATCH($A14,$B$32:$Y$32,0)),">="&K$12)/ROWS($A$33:$A$242) -> 0.11428571 | L14: =1-_xlfn.BETA.DIST(VLOOKUP($A14,NB_p!$A$2:$G$25,2,FALSE),VLOOKUP($A14,NB_r!$A$2:$G$25,2,FALSE),L$12,TRUE) -> 0.03799663 | M14: =COUNTIF(INDEX($B$33:$Y$242,0,MATCH($A14,$B$32:$Y$32,0)),">="&M$12)/ROWS($A$33:$A$242) -> 0.042857143
A15: 19 | B15: =1-_xlfn.BETA.DIST(VLOOKUP($A15,NB_p!$A$2:$G$25,2,FALSE),VLOOKUP($A15,NB_r!$A$2:$G$25,2,FALSE),B$12,TRUE) -> 0.99590314 | C15: =COUNTIF(INDEX($B$33:$Y$242,0,MATCH($A15,$B$32:$Y$32,0)),">="&C$12)/ROWS($A$33:$A$242) -> 1 | D15: =1-_xlfn.BETA.DIST(VLOOKUP($A15,NB_p!$A$2:$G$25,2,FALSE),VLOOKUP($A15,NB_r!$A$2:$G$25,2,FALSE),D$12,TRUE) -> 0.91140649 | E15: =COUNTIF(INDEX($B$33:$Y$242,0,MATCH($A15,$B$32:$Y$32,0)),">="&E$12)/ROWS($A$33:$A$242) -> 0.92380952 | F15: =1-_xlfn.BETA.DIST(VLOOKUP($A15,NB_p!$A$2:$G$25,2,FALSE),VLOOKUP($A15,NB_r!$A$2:$G$25,2,FALSE),F$12,TRUE) -> 0.63595652 | G15: =COUNTIF(INDEX($B$33:$Y$242,0,MATCH($A15,$B$32:$Y$32,0)),">="&G$12)/ROWS($A$33:$A$242) -> 0.63809524 | H15: =1-_xlfn.BETA.DIST(VLOOKUP($A15,NB_p!$A$2:$G$25,2,FALSE),VLOOKUP($A15,NB_r!$A$2:$G$25,2,FALSE),H$12,TRUE) -> 0.31066151 | I15: =COUNTIF(INDEX($B$33:$Y$242,0,MATCH($A15,$B$32:$Y$32,0)),">="&I$12)/ROWS($A$33:$A$242) -> 0.32857143 | J15: =1-_xlfn.BETA.DIST(VLOOKUP($A15,NB_p!$A$2:$G$25,2,FALSE),VLOOKUP($A15,NB_r!$A$2:$G$25,2,FALSE),J$12,TRUE) -> 0.10921704 | K15: =COUNTIF(INDEX($B$33:$Y$242,0,MATCH($A15,$B$32:$Y$32,0)),">="&K$12)/ROWS($A$33:$A$242) -> 0.071428571 | L15: =1-_xlfn.BETA.DIST(VLOOKUP($A15,NB_p!$A$2:$G$25,2,FALSE),VLOOKUP($A15,NB_r!$A$2:$G$25,2,FALSE),L$12,TRUE) -> 0.029244558 | M15: =COUNTIF(INDEX($B$33:$Y$242,0,MATCH($A15,$B$32:$Y$32,0)),">="&M$12)/ROWS($A$33:$A$242) -> 0.014285714
A16: 20 | B16: =1-_xlfn.BETA.DIST(VLOOKUP($A16,NB_p!$A$2:$G$25,2,FALSE),VLOOKUP($A16,NB_r!$A$2:$G$25,2,FALSE),B$12,TRUE) -> 0.98531208 | C16: =COUNTIF(INDEX($B$33:$Y$242,0,MATCH($A16,$B$32:$Y$32,0)),">="&C$12)/ROWS($A$33:$A$242) -> 1 | D16: =1-_xlfn.BETA.DIST(VLOOKUP($A16,NB_p!$A$2:$G$25,2,FALSE),VLOOKUP($A16,NB_r!$A$2:$G$25,2,FALSE),D$12,TRUE) -> 0.8112156 | E16: =COUNTIF(INDEX($B$33:$Y$242,0,MATCH($A16,$B$32:$Y$32,0)),">="&E$12)/ROWS($A$33:$A$242) -> 0.85238095 | F16: =1-_xlfn.BETA.DIST(VLOOKUP($A16,NB_p!$A$2:$G$25,2,FALSE),VLOOKUP($A16,NB_r!$A$2:$G$25,2,FALSE),F$12,TRUE) -> 0.45548671 | G16: =COUNTIF(INDEX($B$33:$Y$242,0,MATCH($A16,$B$32:$Y$32,0)),">="&G$12)/ROWS($A$33:$A$242) -> 0.44761905 | H16: =1-_xlfn.BETA.DIST(VLOOKUP($A16,NB_p!$A$2:$G$25,2,FALSE),VLOOKUP($A16,NB_r!$A$2:$G$25,2,FALSE),H$12,TRUE) -> 0.17283107 | I16: =COUNTIF(INDEX($B$33:$Y$242,0,MATCH($A16,$B$32:$Y$32,0)),">="&I$12)/ROWS($A$33:$A$242) -> 0.13333333 | J16: =1-_xlfn.BETA.DIST(VLOOKUP($A16,NB_p!$A$2:$G$25,2,FALSE),VLOOKUP($A16,NB_r!$A$2:$G$25,2,FALSE),J$12,TRUE) -> 0.047613183 | K16: =COUNTIF(INDEX($B$33:$Y$242,0,MATCH($A16,$B$32:$Y$32,0)),">="&K$12)/ROWS($A$33:$A$242) -> 0.042857143 | L16: =1-_xlfn.BETA.DIST(VLOOKUP($A16,NB_p!$A$2:$G$25,2,FALSE),VLOOKUP($A16,NB_r!$A$2:$G$25,2,FALSE),L$12,TRUE) -> 0.010216419 | M16: =COUNTIF(INDEX($B$33:$Y$242,0,MATCH($A16,$B$32:$Y$32,0)),">="&M$12)/ROWS($A$33:$A$242) -> 0.0095238095
A17: 21 | B17: =1-_xlfn.BETA.DIST(VLOOKUP($A17,NB_p!$A$2:$G$25,2,FALSE),VLOOKUP($A17,NB_r!$A$2:$G$25,2,FALSE),B$12,TRUE) -> 0.94849934 | C17: =COUNTIF(INDEX($B$33:$Y$242,0,MATCH($A17,$B$32:$Y$32,0)),">="&C$12)/ROWS($A$33:$A$242) -> 0.98571429 | D17: =1-_xlfn.BETA.DIST(VLOOKUP($A17,NB_p!$A$2:$G$25,2,FALSE),VLOOKUP($A17,NB_r!$A$2:$G$25,2,FALSE),D$12,TRUE) -> 0.69859628 | E17: =COUNTIF(INDEX($B$33:$Y$242,0,MATCH($A17,$B$32:$Y$32,0)),">="&E$12)/ROWS($A$33:$A$242) -> 0.74285714 | F17: =1-_xlfn.BETA.DIST(VLOOKUP($A17,NB_p!$A$2:$G$25,2,FALSE),VLOOKUP($A17,NB_r!$A$2:$G$25,2,FALSE),F$12,TRUE) -> 0.38181604 | G17: =COUNTIF(INDEX($B$33:$Y$242,0,MATCH($A17,$B$32:$Y$32,0)),">="&G$12)/ROWS($A$33:$A$242) -> 0.34761905 | H17: =1-_xlfn.BETA.DIST(VLOOKUP($A17,NB_p!$A$2:$G$25,2,FALSE),VLOOKUP($A17,NB_r!$A$2:$G$25,2,FALSE),H$12,TRUE) -> 0.16502855 | I17: =COUNTIF(INDEX($B$33:$Y$242,0,MATCH($A17,$B$32:$Y$32,0)),">="&I$12)/ROWS($A$33:$A$242) -> 0.11428571 | J17: =1-_xlfn.BETA.DIST(VLOOKUP($A17,NB_p!$A$2:$G$25,2,FALSE),VLOOKUP($A17,NB_r!$A$2:$G$25,2,FALSE),J$12,TRUE) -> 0.060024999 | K17: =COUNTIF(INDEX($B$33:$Y$242,0,MATCH($A17,$B$32:$Y$32,0)),">="&K$12)/ROWS($A$33:$A$242) -> 0.028571429 | L17: =1-_xlfn.BETA.DIST(VLOOKUP($A17,NB_p!$A$2:$G$25,2,FALSE),VLOOKUP($A17,NB_r!$A$2:$G$25,2,FALSE),L$12,TRUE) -> 0.019204071 | M17: =COUNTIF(INDEX($B$33:$Y$242,0,MATCH($A17,$B$32:$Y$32,0)),">="&M$12)/ROWS($A$33:$A$242) -> 0.014285714
A18: 22 | B18: =1-_xlfn.BETA.DIST(VLOOKUP($A18,NB_p!$A$2:$G$25,2,FALSE),VLOOKUP($A18,NB_r!$A$2:$G$25,2,FALSE),B$12,TRUE) -> 0.93971254 | C18: =COUNTIF(INDEX($B$33:$Y$242,0,MATCH($A18,$B$32:$Y$32,0)),">="&C$12)/ROWS($A$33:$A$242) -> 0.95714286 | D18: =1-_xlfn.BETA.DIST(VLOOKUP($A18,NB_p!$A$2:$G$25,2,FALSE),VLOOKUP($A18,NB_r!$A$2:$G$25,2,FALSE),D$12,TRUE) -> 0.59277187 | E18: =COUNTIF(INDEX($B$33:$Y$242,0,MATCH($A18,$B$32:$Y$32,0)),">="&E$12)/ROWS($A$33:$A$242) -> 0.61904762 | F18: =1-_xlfn.BETA.DIST(VLOOKUP($A18,NB_p!$A$2:$G$25,2,FALSE),VLOOKUP($A18,NB_r!$A$2:$G$25,2,FALSE),F$12,TRUE) -> 0.22134433 | G18: =COUNTIF(INDEX($B$33:$Y$242,0,MATCH($A18,$B$32:$Y$32,0)),">="&G$12)/ROWS($A$33:$A$242) -> 0.17619048 | H18: =1-_xlfn.BETA.DIST(VLOOKUP($A18,NB_p!$A$2:$G$25,2,FALSE),VLOOKUP($A18,NB_r!$A$2:$G$25,2,FALSE),H$12,TRUE) -> 0.054551533 | I18: =COUNTIF(INDEX($B$33:$Y$242,0,MATCH($A18,$B$32:$Y$32,0)),">="&I$12)/ROWS($A$33:$A$242) -> 0.038095238 | J18: =1-_xlfn.BETA.DIST(VLOOKUP($A18,NB_p!$A$2:$G$25,2,FALSE),VLOOKUP($A18,NB_r!$A$2:$G$25,2,FALSE),J$12,TRUE) -> 0.0099320855 | K18: =COUNTIF(INDEX($B$33:$Y$242,0,MATCH($A18,$B$32:$Y$32,0)),">="&K$12)/ROWS($A$33:$A$242) -> 0.019047619 | L18: =1-_xlfn.BETA.DIST(VLOOKUP($A18,NB_p!$A$2:$G$25,2,FALSE),VLOOKUP($A18,NB_r!$A$2:$G$25,2,FALSE),L$12,TRUE) -> 0.0014459467 | M18: =COUNTIF(INDEX($B$33:$Y$242,0,MATCH($A18,$B$32:$Y$32,0)),">="&M$12)/ROWS($A$33:$A$242) -> 0.014285714
B19: NG_P(X≥10) | C19: Actual_P(X≥10) | D19: NG_P(X≥15) | E19: Actual_P(X≥15) | F19: NG_P(X≥20) | G19: Actual_P(X≥20) | H19: NG_P(X≥25) | I19: Actual_P(X≥25) | J19: NG_P(X≥30) | K19: Actual_P(X≥30) | L19: NG_P(X≥35) | M19: Actual_P(X≥35) | N19: NG_P(X≥40) | O19: Actual_P(X≥40)
A20: High_frequency_hour | B20: 10 | C20: 10 | D20: 15 | E20: 15 | F20: 20 | G20: 20 | H20: 25 | I20: 25 | J20: 30 | K20: 30 | L20: 35 | M20: 35 | N20: 40 | O20: 40
A21: 9 | B21: =1-_xlfn.BETA.DIST(VLOOKUP($A21,NB_p!$A$2:$G$25,2,FALSE),VLOOKUP($A21,NB_r!$A$2:$G$25,2,FALSE),B$20,TRUE) -> 0.90766882 | C21: =COUNTIF(INDEX($B$33:$Y$242,0,MATCH($A21,$B$32:$Y$32,0)),">="&C$20)/ROWS($A$33:$A$242) -> 0.88571429 | D21: =1-_xlfn.BETA.DIST(VLOOKUP($A21,NB_p!$A$2:$G$25,2,FALSE),VLOOKUP($A21,NB_r!$A$2:$G$25,2,FALSE),D$20,TRUE) -> 0.63528732 | E21: =COUNTIF(INDEX($B$33:$Y$242,0,MATCH($A21,$B$32:$Y$32,0)),">="&E$20)/ROWS($A$33:$A$242) -> 0.69047619 | F21: =1-_xlfn.BETA.DIST(VLOOKUP($A21,NB_p!$A$2:$G$25,2,FALSE),VLOOKUP($A21,NB_r!$A$2:$G$25,2,FALSE),F$20,TRUE) -> 0.31712606 | G21: =COUNTIF(INDEX($B$33:$Y$242,0,MATCH($A21,$B$32:$Y$32,0)),">="&G$20)/ROWS($A$33:$A$242) -> 0.2952381 | H21: =1-_xlfn.BETA.DIST(VLOOKUP($A21,NB_p!$A$2:$G$25,2,FALSE),VLOOKUP($A21,NB_r!$A$2:$G$25,2,FALSE),H$20,TRUE) -> 0.11630825 | I21: =COUNTIF(INDEX($B$33:$Y$242,0,MATCH($A21,$B$32:$Y$32,0)),">="&I$20)/ROWS($A$33:$A$242) -> 0.10952381 | J21: =1-_xlfn.BETA.DIST(VLOOKUP($A21,NB_p!$A$2:$G$25,2,FALSE),VLOOKUP($A21,NB_r!$A$2:$G$25,2,FALSE),J$20,TRUE) -> 0.033089905 | K21: =COUNTIF(INDEX($B$33:$Y$242,0,MATCH($A21,$B$32:$Y$32,0)),">="&K$20)/ROWS($A$33:$A$242) -> 0.038095238 | L21: =1-_xlfn.BETA.DIST(VLOOKUP($A21,NB_p!$A$2:$G$25,2,FALSE),VLOOKUP($A21,NB_r!$A$2:$G$25,2,FALSE),L$20,TRUE) -> 0.0076694401 | M21: =COUNTIF(INDEX($B$33:$Y$242,0,MATCH($A21,$B$32:$Y$32,0)),">="&M$20)/ROWS($A$33:$A$242) -> 0.014285714 | N21: =1-_xlfn.BETA.DIST(VLOOKUP($A21,NB_p!$A$2:$G$25,2,FALSE),VLOOKUP($A21,NB_r!$A$2:$G$25,2,FALSE),N$20,TRUE) -> 0.0015053038 | O21: =COUNTIF(INDEX($B$33:$Y$242,0,MATCH($A21,$B$32:$Y$32,0)),">="&O$20)/ROWS($A$33:$A$242) -> 0
A22: 10 | B22: =1-_xlfn.BETA.DIST(VLOOKUP($A22,NB_p!$A$2:$G$25,2,FALSE),VLOOKUP($A22,NB_r!$A$2:$G$25,2,FALSE),B$20,TRUE) -> 0.91185271 | C22: =COUNTIF(INDEX($B$33:$Y$242,0,MATCH($A22,$B$32:$Y$32,0)),">="&C$20)/ROWS($A$33:$A$242) -> 0.93809524 | D22: =1-_xlfn.BETA.DIST(VLOOKUP($A22,NB_p!$A$2:$G$25,2,FALSE),VLOOKUP($A22,NB_r!$A$2:$G$25,2,FALSE),D$20,TRUE) -> 0.70122206 | E22: =COUNTIF(INDEX($B$33:$Y$242,0,MATCH($A22,$B$32:$Y$32,0)),">="&E$20)/ROWS($A$33:$A$242) -> 0.74285714 | F22: =1-_xlfn.BETA.DIST(VLOOKUP($A22,NB_p!$A$2:$G$25,2,FALSE),VLOOKUP($A22,NB_r!$A$2:$G$25,2,FALSE),F$20,TRUE) -> 0.44003661 | G22: =COUNTIF(INDEX($B$33:$Y$242,0,MATCH($A22,$B$32:$Y$32,0)),">="&G$20)/ROWS($A$33:$A$242) -> 0.41904762 | H22: =1-_xlfn.BETA.DIST(VLOOKUP($A22,NB_p!$A$2:$G$25,2,FALSE),VLOOKUP($A22,NB_r!$A$2:$G$25,2,FALSE),H$20,TRUE) -> 0.23048385 | I22: =COUNTIF(INDEX($B$33:$Y$242,0,MATCH($A22,$B$32:$Y$32,0)),">="&I$20)/ROWS($A$33:$A$242) -> 0.16666667 | J22: =1-_xlfn.BETA.DIST(VLOOKUP($A22,NB_p!$A$2:$G$25,2,FALSE),VLOOKUP($A22,NB_r!$A$2:$G$25,2,FALSE),J$20,TRUE) -> 0.10406904 | K22: =COUNTIF(INDEX($B$33:$Y$242,0,MATCH($A22,$B$32:$Y$32,0)),">="&K$20)/ROWS($A$33:$A$242) -> 0.071428571 | L22: =1-_xlfn.BETA.DIST(VLOOKUP($A22,NB_p!$A$2:$G$25,2,FALSE),VLOOKUP($A22,NB_r!$A$2:$G$25,2,FALSE),L$20,TRUE) -> 0.041677467 | M22: =COUNTIF(INDEX($B$33:$Y$242,0,MATCH($A22,$B$32:$Y$32,0)),">="&M$20)/ROWS($A$33:$A$242) -> 0.023809524 | N22: =1-_xlfn.BETA.DIST(VLOOKUP($A22,NB_p!$A$2:$G$25,2,FALSE),VLOOKUP($A22,NB_r!$A$2:$G$25,2,FALSE),N$20,TRUE) -> 0.015141533 | O22: =COUNTIF(INDEX($B$33:$Y$242,0,MATCH($A22,$B$32:$Y$32,0)),">="&O$20)/ROWS($A$33:$A$242) -> 0.0095238095
A23: 11 | B23: =1-_xlfn.BETA.DIST(VLOOKUP($A23,NB_p!$A$2:$G$25,2,FALSE),VLOOKUP($A23,NB_r!$A$2:$G$25,2,FALSE),B$20,TRUE) -> 0.90932319 | C23: =COUNTIF(INDEX($B$33:$Y$242,0,MATCH($A23,$B$32:$Y$32,0)),">="&C$20)/ROWS($A$33:$A$242) -> 0.95238095 | D23: =1-_xlfn.BETA.DIST(VLOOKUP($A23,NB_p!$A$2:$G$25,2,FALSE),VLOOKUP($A23,NB_r!$A$2:$G$25,2,FALSE),D$20,TRUE) -> 0.71476455 | E23: =COUNTIF(INDEX($B$33:$Y$242,0,MATCH($A23,$B$32:$Y$32,0)),">="&E$20)/ROWS($A$33:$A$242) -> 0.8 | F23: =1-_xlfn.BETA.DIST(VLOOKUP($A23,NB_p!$A$2:$G$25,2,FALSE),VLOOKUP($A23,NB_r!$A$2:$G$25,2,FALSE),F$20,TRUE) -> 0.47514041 | G23: =COUNTIF(INDEX($B$33:$Y$242,0,MATCH($A23,$B$32:$Y$32,0)),">="&G$20)/ROWS($A$33:$A$242) -> 0.49047619 | H23: =1-_xlfn.BETA.DIST(VLOOKUP($A23,NB_p!$A$2:$G$25,2,FALSE),VLOOKUP($A23,NB_r!$A$2:$G$25,2,FALSE),H$20,TRUE) -> 0.27281596 | I23: =COUNTIF(INDEX($B$33:$Y$242,0,MATCH($A23,$B$32:$Y$32,0)),">="&I$20)/ROWS($A$33:$A$242) -> 0.2047619 | J23: =1-_xlfn.BETA.DIST(VLOOKUP($A23,NB_p!$A$2:$G$25,2,FALSE),VLOOKUP($A23,NB_r!$A$2:$G$25,2,FALSE),J$20,TRUE) -> 0.13895181 | K23: =COUNTIF(INDEX($B$33:$Y$242,0,MATCH($A23,$B$32:$Y$32,0)),">="&K$20)/ROWS($A$33:$A$242) -> 0.052380952 | L23: =1-_xlfn.BETA.DIST(VLOOKUP($A23,NB_p!$A$2:$G$25,2,FALSE),VLOOKUP($A23,NB_r!$A$2:$G$25,2,FALSE),L$20,TRUE) -> 0.064237865 | M23: =COUNTIF(INDEX($B$33:$Y$242,0,MATCH($A23,$B$32:$Y$32,0)),">="&M$20)/ROWS($A$33:$A$242) -> 0.014285714 | N23: =1-_xlfn.BETA.DIST(VLOOKUP($A23,NB_p!$A$2:$G$25,2,FALSE),VLOOKUP($A23,NB_r!$A$2:$G$25,2,FALSE),N$20,TRUE) -> 0.02744861 | O23: =COUNTIF(INDEX($B$33:$Y$242,0,MATCH($A23,$B$32:$Y$32,0)),">="&O$20)/ROWS($A$33:$A$242) -> 0.0095238095
A24: 12 | B24: =1-_xlfn.BETA.DIST(VLOOKUP($A24,NB_p!$A$2:$G$25,2,FALSE),VLOOKUP($A24,NB_r!$A$2:$G$25,2,FALSE),B$20,TRUE) -> 0.71816706 | C24: =COUNTIF(INDEX($B$33:$Y$242,0,MATCH($A24,$B$32:$Y$32,0)),">="&C$20)/ROWS($A$33:$A$242) -> 0.98571429 | D24: =1-_xlfn.BETA.DIST(VLOOKUP($A24,NB_p!$A$2:$G$25,2,FALSE),VLOOKUP($A24,NB_r!$A$2:$G$25,2,FALSE),D$20,TRUE) -> 0.57169203 | E24: =COUNTIF(INDEX($B$33:$Y$242,0,MATCH($A24,$B$32:$Y$32,0)),">="&E$20)/ROWS($A$33:$A$242) -> 0.82380952 | F24: =1-_xlfn.BETA.DIST(VLOOKUP($A24,NB_p!$A$2:$G$25,2,FALSE),VLOOKUP($A24,NB_r!$A$2:$G$25,2,FALSE),F$20,TRUE) -> 0.44699486 | G24: =COUNTIF(INDEX($B$33:$Y$242,0,MATCH($A24,$B$32:$Y$32,0)),">="&G$20)/ROWS($A$33:$A$242) -> 0.51428571 | H24: =1-_xlfn.BETA.DIST(VLOOKUP($A24,NB_p!$A$2:$G$25,2,FALSE),VLOOKUP($A24,NB_r!$A$2:$G$25,2,FALSE),H$20,TRUE) -> 0.34523847 | I24: =COUNTIF(INDEX($B$33:$Y$242,0,MATCH($A24,$B$32:$Y$32,0)),">="&I$20)/ROWS($A$33:$A$242) -> 0.23809524 | J24: =1-_xlfn.BETA.DIST(VLOOKUP($A24,NB_p!$A$2:$G$25,2,FALSE),VLOOKUP($A24,NB_r!$A$2:$G$25,2,FALSE),J$20,TRUE) -> 0.26426543 | K24: =COUNTIF(INDEX($B$33:$Y$242,0,MATCH($A24,$B$32:$Y$32,0)),">="&K$20)/ROWS($A$33:$A$242) -> 0.095238095 | L24: =1-_xlfn.BETA.DIST(VLOOKUP($A24,NB_p!$A$2:$G$25,2,FALSE),VLOOKUP($A24,NB_r!$A$2:$G$25,2,FALSE),L$20,TRUE) -> 0.20089798 | M24: =COUNTIF(INDEX($B$33:$Y$242,0,MATCH($A24,$B$32:$Y$32,0)),">="&M$20)/ROWS($A$33:$A$242) -> 0.052380952 | N24: =1-_xlfn.BETA.DIST(VLOOKUP($A24,NB_p!$A$2:$G$25,2,FALSE),VLOOKUP($A24,NB_r!$A$2:$G$25,2,FALSE),N$20,TRUE) -> 0.15189502 | O24: =COUNTIF(INDEX($B$33:$Y$242,0,MATCH($A24,$B$32:$Y$32,0)),">="&O$20)/ROWS($A$33:$A$242) -> 0.023809524
A25: 13 | B25: =1-_xlfn.BETA.DIST(VLOOKUP($A25,NB_p!$A$2:$G$25,2,FALSE),VLOOKUP($A25,NB_r!$A$2:$G$25,2,FALSE),B$20,TRUE) -> 0.67188532 | C25: =COUNTIF(INDEX($B$33:$Y$242,0,MATCH($A25,$B$32:$Y$32,0)),">="&C$20)/ROWS($A$33:$A$242) -> 0.98571429 | D25: =1-_xlfn.BETA.DIST(VLOOKUP($A25,NB_p!$A$2:$G$25,2,FALSE),VLOOKUP($A25,NB_r!$A$2:$G$25,2,FALSE),D$20,TRUE) -> 0.5360323 | E25: =COUNTIF(INDEX($B$33:$Y$242,0,MATCH($A25,$B$32:$Y$32,0)),">="&E$20)/ROWS($A$33:$A$242) -> 0.83333333 | F25: =1-_xlfn.BETA.DIST(VLOOKUP($A25,NB_p!$A$2:$G$25,2,FALSE),VLOOKUP($A25,NB_r!$A$2:$G$25,2,FALSE),F$20,TRUE) -> 0.42487856 | G25: =COUNTIF(INDEX($B$33:$Y$242,0,MATCH($A25,$B$32:$Y$32,0)),">="&G$20)/ROWS($A$33:$A$242) -> 0.47619048 | H25: =1-_xlfn.BETA.DIST(VLOOKUP($A25,NB_p!$A$2:$G$25,2,FALSE),VLOOKUP($A25,NB_r!$A$2:$G$25,2,FALSE),H$20,TRUE) -> 0.33532222 | I25: =COUNTIF(INDEX($B$33:$Y$242,0,MATCH($A25,$B$32:$Y$32,0)),">="&I$20)/ROWS($A$33:$A$242) -> 0.23333333 | J25: =1-_xlfn.BETA.DIST(VLOOKUP($A25,NB_p!$A$2:$G$25,2,FALSE),VLOOKUP($A25,NB_r!$A$2:$G$25,2,FALSE),J$20,TRUE) -> 0.26381922 | K25: =COUNTIF(INDEX($B$33:$Y$242,0,MATCH($A25,$B$32:$Y$32,0)),">="&K$20)/ROWS($A$33:$A$242) -> 0.1047619 | L25: =1-_xlfn.BETA.DIST(VLOOKUP($A25,NB_p!$A$2:$G$25,2,FALSE),VLOOKUP($A25,NB_r!$A$2:$G$25,2,FALSE),L$20,TRUE) -> 0.20707214 | M25: =COUNTIF(INDEX($B$33:$Y$242,0,MATCH($A25,$B$32:$Y$32,0)),">="&M$20)/ROWS($A$33:$A$242) -> 0.042857143 | N25: =1-_xlfn.BETA.DIST(VLOOKUP($A25,NB_p!$A$2:$G$25,2,FALSE),VLOOKUP($A25,NB_r!$A$2:$G$25,2,FALSE),N$20,TRUE) -> 0.16222778 | O25: =COUNTIF(INDEX($B$33:$Y$242,0,MATCH($A25,$B$32:$Y$32,0)),">="&O$20)/ROWS($A$33:$A$242) -> 0.028571429
A26: 14 | B26: =1-_xlfn.BETA.DIST(VLOOKUP($A26,NB_p!$A$2:$G$25,2,FALSE),VLOOKUP($A26,NB_r!$A$2:$G$25,2,FALSE),B$20,TRUE) -> 0.82616412 | C26: =COUNTIF(INDEX($B$33:$Y$242,0,MATCH($A26,$B$32:$Y$32,0)),">="&C$20)/ROWS($A$33:$A$242) -> 0.93809524 | D26: =1-_xlfn.BETA.DIST(VLOOKUP($A26,NB_p!$A$2:$G$25,2,FALSE),VLOOKUP($A26,NB_r!$A$2:$G$25,2,FALSE),D$20,TRUE) -> 0.65584196 | E26: =COUNTIF(INDEX($B$33:$Y$242,0,MATCH($A26,$B$32:$Y$32,0)),">="&E$20)/ROWS($A$33:$A$242) -> 0.78571429 | F26: =1-_xlfn.BETA.DIST(VLOOKUP($A26,NB_p!$A$2:$G$25,2,FALSE),VLOOKUP($A26,NB_r!$A$2:$G$25,2,FALSE),F$20,TRUE) -> 0.48830074 | G26: =COUNTIF(INDEX($B$33:$Y$242,0,MATCH($A26,$B$32:$Y$32,0)),">="&G$20)/ROWS($A$33:$A$242) -> 0.53333333 | H26: =1-_xlfn.BETA.DIST(VLOOKUP($A26,NB_p!$A$2:$G$25,2,FALSE),VLOOKUP($A26,NB_r!$A$2:$G$25,2,FALSE),H$20,TRUE) -> 0.34647262 | I26: =COUNTIF(INDEX($B$33:$Y$242,0,MATCH($A26,$B$32:$Y$32,0)),">="&I$20)/ROWS($A$33:$A$242) -> 0.24761905 | J26: =1-_xlfn.BETA.DIST(VLOOKUP($A26,NB_p!$A$2:$G$25,2,FALSE),VLOOKUP($A26,NB_r!$A$2:$G$25,2,FALSE),J$20,TRUE) -> 0.23692572 | K26: =COUNTIF(INDEX($B$33:$Y$242,0,MATCH($A26,$B$32:$Y$32,0)),">="&K$20)/ROWS($A$33:$A$242) -> 0.10952381 | L26: =1-_xlfn.BETA.DIST(VLOOKUP($A26,NB_p!$A$2:$G$25,2,FALSE),VLOOKUP($A26,NB_r!$A$2:$G$25,2,FALSE),L$20,TRUE) -> 0.15738099 | M26: =COUNTIF(INDEX($B$33:$Y$242,0,MATCH($A26,$B$32:$Y$32,0)),">="&M$20)/ROWS($A$33:$A$242) -> 0.057142857 | N26: =1-_xlfn.BETA.DIST(VLOOKUP($A26,NB_p!$A$2:$G$25,2,FALSE),VLOOKUP($A26,NB_r!$A$2:$G$25,2,FALSE),N$20,TRUE) -> 0.1021332 | O26: =COUNTIF(INDEX($B$33:$Y$242,0,MATCH($A26,$B$32:$Y$32,0)),">="&O$20)/ROWS($A$33:$A$242) -> 0.038095238
A27: 15 | B27: =1-_xlfn.BETA.DIST(VLOOKUP($A27,NB_p!$A$2:$G$25,2,FALSE),VLOOKUP($A27,NB_r!$A$2:$G$25,2,FALSE),B$20,TRUE) -> 0.89179976 | C27: =COUNTIF(INDEX($B$33:$Y$242,0,MATCH($A27,$B$32:$Y$32,0)),">="&C$20)/ROWS($A$33:$A$242) -> 0.96666667 | D27: =1-_xlfn.BETA.DIST(VLOOKUP($A27,NB_p!$A$2:$G$25,2,FALSE),VLOOKUP($A27,NB_r!$A$2:$G$25,2,FALSE),D$20,TRUE) -> 0.72734135 | E27: =COUNTIF(INDEX($B$33:$Y$242,0,MATCH($A27,$B$32:$Y$32,0)),">="&E$20)/ROWS($A$33:$A$242) -> 0.85714286 | F27: =1-_xlfn.BETA.DIST(VLOOKUP($A27,NB_p!$A$2:$G$25,2,FALSE),VLOOKUP($A27,NB_r!$A$2:$G$25,2,FALSE),F$20,TRUE) -> 0.53792603 | G27: =COUNTIF(INDEX($B$33:$Y$242,0,MATCH($A27,$B$32:$Y$32,0)),">="&G$20)/ROWS($A$33:$A$242) -> 0.60952381 | H27: =1-_xlfn.BETA.DIST(VLOOKUP($A27,NB_p!$A$2:$G$25,2,FALSE),VLOOKUP($A27,NB_r!$A$2:$G$25,2,FALSE),H$20,TRUE) -> 0.36708597 | I27: =COUNTIF(INDEX($B$33:$Y$242,0,MATCH($A27,$B$32:$Y$32,0)),">="&I$20)/ROWS($A$33:$A$242) -> 0.28095238 | J27: =1-_xlfn.BETA.DIST(VLOOKUP($A27,NB_p!$A$2:$G$25,2,FALSE),VLOOKUP($A27,NB_r!$A$2:$G$25,2,FALSE),J$20,TRUE) -> 0.23484413 | K27: =COUNTIF(INDEX($B$33:$Y$242,0,MATCH($A27,$B$32:$Y$32,0)),">="&K$20)/ROWS($A$33:$A$242) -> 0.12857143 | L27: =1-_xlfn.BETA.DIST(VLOOKUP($A27,NB_p!$A$2:$G$25,2,FALSE),VLOOKUP($A27,NB_r!$A$2:$G$25,2,FALSE),L$20,TRUE) -> 0.14263912 | M27: =COUNTIF(INDEX($B$33:$Y$242,0,MATCH($A27,$B$32:$Y$32,0)),">="&M$20)/ROWS($A$33:$A$242) -> 0.061904762 | N27: =1-_xlfn.BETA.DIST(VLOOKUP($A27,NB_p!$A$2:$G$25,2,FALSE),VLOOKUP($A27,NB_r!$A$2:$G$25,2,FALSE),N$20,TRUE) -> 0.083051043 | O27: =COUNTIF(INDEX($B$33:$Y$242,0,MATCH($A27,$B$32:$Y$32,0)),">="&O$20)/ROWS($A$33:$A$242) -> 0.042857143
A28: 16 | B28: =1-_xlfn.BETA.DIST(VLOOKUP($A28,NB_p!$A$2:$G$25,2,FALSE),VLOOKUP($A28,NB_r!$A$2:$G$25,2,FALSE),B$20,TRUE) -> 0.96272083 | C28: =COUNTIF(INDEX($B$33:$Y$242,0,MATCH($A28,$B$32:$Y$32,0)),">="&C$20)/ROWS($A$33:$A$242) -> 0.9952381 | D28: =1-_xlfn.BETA.DIST(VLOOKUP($A28,NB_p!$A$2:$G$25,2,FALSE),VLOOKUP($A28,NB_r!$A$2:$G$25,2,FALSE),D$20,TRUE) -> 0.81756559 | E28: =COUNTIF(INDEX($B$33:$Y$242,0,MATCH($A28,$B$32:$Y$32,0)),">="&E$20)/ROWS($A$33:$A$242) -> 0.85238095 | F28: =1-_xlfn.BETA.DIST(VLOOKUP($A28,NB_p!$A$2:$G$25,2,FALSE),VLOOKUP($A28,NB_r!$A$2:$G$25,2,FALSE),F$20,TRUE) -> 0.5704938 | G28: =COUNTIF(INDEX($B$33:$Y$242,0,MATCH($A28,$B$32:$Y$32,0)),">="&G$20)/ROWS($A$33:$A$242) -> 0.57619048 | H28: =1-_xlfn.BETA.DIST(VLOOKUP($A28,NB_p!$A$2:$G$25,2,FALSE),VLOOKUP($A28,NB_r!$A$2:$G$25,2,FALSE),H$20,TRUE) -> 0.32454277 | I28: =COUNTIF(INDEX($B$33:$Y$242,0,MATCH($A28,$B$32:$Y$32,0)),">="&I$20)/ROWS($A$33:$A$242) -> 0.30952381 | J28: =1-_xlfn.BETA.DIST(VLOOKUP($A28,NB_p!$A$2:$G$25,2,FALSE),VLOOKUP($A28,NB_r!$A$2:$G$25,2,FALSE),J$20,TRUE) -> 0.15395288 | K28: =COUNTIF(INDEX($B$33:$Y$242,0,MATCH($A28,$B$32:$Y$32,0)),">="&K$20)/ROWS($A$33:$A$242) -> 0.11428571 | L28: =1-_xlfn.BETA.DIST(VLOOKUP($A28,NB_p!$A$2:$G$25,2,FALSE),VLOOKUP($A28,NB_r!$A$2:$G$25,2,FALSE),L$20,TRUE) -> 0.062656099 | M28: =COUNTIF(INDEX($B$33:$Y$242,0,MATCH($A28,$B$32:$Y$32,0)),">="&M$20)/ROWS($A$33:$A$242) -> 0.042857143 | N28: =1-_xlfn.BETA.DIST(VLOOKUP($A28,NB_p!$A$2:$G$25,2,FALSE),VLOOKUP($A28,NB_r!$A$2:$G$25,2,FALSE),N$20,TRUE) -> 0.022446388 | O28: =COUNTIF(INDEX($B$33:$Y$242,0,MATCH($A28,$B$32:$Y$32,0)),">="&O$20)/ROWS($A$33:$A$242) -> 0.019047619
A29: 17 | B29: =1-_xlfn.BETA.DIST(VLOOKUP($A29,NB_p!$A$2:$G$25,2,FALSE),VLOOKUP($A29,NB_r!$A$2:$G$25,2,FALSE),B$20,TRUE) -> 0.92824137 | C29: =COUNTIF(INDEX($B$33:$Y$242,0,MATCH($A29,$B$32:$Y$32,0)),">="&C$20)/ROWS($A$33:$A$242) -> 0.95714286 | D29: =1-_xlfn.BETA.DIST(VLOOKUP($A29,NB_p!$A$2:$G$25,2,FALSE),VLOOKUP($A29,NB_r!$A$2:$G$25,2,FALSE),D$20,TRUE) -> 0.76193733 | E29: =COUNTIF(INDEX($B$33:$Y$242,0,MATCH($A29,$B$32:$Y$32,0)),">="&E$20)/ROWS($A$33:$A$242) -> 0.8047619 | F29: =1-_xlfn.BETA.DIST(VLOOKUP($A29,NB_p!$A$2:$G$25,2,FALSE),VLOOKUP($A29,NB_r!$A$2:$G$25,2,FALSE),F$20,TRUE) -> 0.53953418 | G29: =COUNTIF(INDEX($B$33:$Y$242,0,MATCH($A29,$B$32:$Y$32,0)),">="&G$20)/ROWS($A$33:$A$242) -> 0.5047619 | H29: =1-_xlfn.BETA.DIST(VLOOKUP($A29,NB_p!$A$2:$G$25,2,FALSE),VLOOKUP($A29,NB_r!$A$2:$G$25,2,FALSE),H$20,TRUE) -> 0.33431999 | I29: =COUNTIF(INDEX($B$33:$Y$242,0,MATCH($A29,$B$32:$Y$32,0)),">="&I$20)/ROWS($A$33:$A$242) -> 0.2952381 | J29: =1-_xlfn.BETA.DIST(VLOOKUP($A29,NB_p!$A$2:$G$25,2,FALSE),VLOOKUP($A29,NB_r!$A$2:$G$25,2,FALSE),J$20,TRUE) -> 0.18530517 | K29: =COUNTIF(INDEX($B$33:$Y$242,0,MATCH($A29,$B$32:$Y$32,0)),">="&K$20)/ROWS($A$33:$A$242) -> 0.17142857 | L29: =1-_xlfn.BETA.DIST(VLOOKUP($A29,NB_p!$A$2:$G$25,2,FALSE),VLOOKUP($A29,NB_r!$A$2:$G$25,2,FALSE),L$20,TRUE) -> 0.093748425 | M29: =COUNTIF(INDEX($B$33:$Y$242,0,MATCH($A29,$B$32:$Y$32,0)),">="&M$20)/ROWS($A$33:$A$242) -> 0.080952381 | N29: =1-_xlfn.BETA.DIST(VLOOKUP($A29,NB_p!$A$2:$G$25,2,FALSE),VLOOKUP($A29,NB_r!$A$2:$G$25,2,FALSE),N$20,TRUE) -> 0.044007486 | O29: =COUNTIF(INDEX($B$33:$Y$242,0,MATCH($A29,$B$32:$Y$32,0)),">="&O$20)/ROWS($A$33:$A$242) -> 0.047619048
A30: 18 | B30: =1-_xlfn.BETA.DIST(VLOOKUP($A30,NB_p!$A$2:$G$25,2,FALSE),VLOOKUP($A30,NB_r!$A$2:$G$25,2,FALSE),B$20,TRUE) -> 0.93931125 | C30: =COUNTIF(INDEX($B$33:$Y$242,0,MATCH($A30,$B$32:$Y$32,0)),">="&C$20)/ROWS($A$33:$A$242) -> 0.94761905 | D30: =1-_xlfn.BETA.DIST(VLOOKUP($A30,NB_p!$A$2:$G$25,2,FALSE),VLOOKUP($A30,NB_r!$A$2:$G$25,2,FALSE),D$20,TRUE) -> 0.72721764 | E30: =COUNTIF(INDEX($B$33:$Y$242,0,MATCH($A30,$B$32:$Y$32,0)),">="&E$20)/ROWS($A$33:$A$242) -> 0.72857143 | F30: =1-_xlfn.BETA.DIST(VLOOKUP($A30,NB_p!$A$2:$G$25,2,FALSE),VLOOKUP($A30,NB_r!$A$2:$G$25,2,FALSE),F$20,TRUE) -> 0.42657931 | G30: =COUNTIF(INDEX($B$33:$Y$242,0,MATCH($A30,$B$32:$Y$32,0)),">="&G$20)/ROWS($A$33:$A$242) -> 0.43333333 | H30: =1-_xlfn.BETA.DIST(VLOOKUP($A30,NB_p!$A$2:$G$25,2,FALSE),VLOOKUP($A30,NB_r!$A$2:$G$25,2,FALSE),H$20,TRUE) -> 0.19114186 | I30: =COUNTIF(INDEX($B$33:$Y$242,0,MATCH($A30,$B$32:$Y$32,0)),">="&I$20)/ROWS($A$33:$A$242) -> 0.18095238 | J30: =1-_xlfn.BETA.DIST(VLOOKUP($A30,NB_p!$A$2:$G$25,2,FALSE),VLOOKUP($A30,NB_r!$A$2:$G$25,2,FALSE),J$20,TRUE) -> 0.068090344 | K30: =COUNTIF(INDEX($B$33:$Y$242,0,MATCH($A30,$B$32:$Y$32,0)),">="&K$20)/ROWS($A$33:$A$242) -> 0.061904762 | L30: =1-_xlfn.BETA.DIST(VLOOKUP($A30,NB_p!$A$2:$G$25,2,FALSE),VLOOKUP($A30,NB_r!$A$2:$G$25,2,FALSE),L$20,TRUE) -> 0.020088517 | M30: =COUNTIF(INDEX($B$33:$Y$242,0,MATCH($A30,$B$32:$Y$32,0)),">="&M$20)/ROWS($A$33:$A$242) -> 0.014285714 | N30: =1-_xlfn.BETA.DIST(VLOOKUP($A30,NB_p!$A$2:$G$25,2,FALSE),VLOOKUP($A30,NB_r!$A$2:$G$25,2,FALSE),N$20,TRUE) -> 0.0050782608 | O30: =COUNTIF(INDEX($B$33:$Y$242,0,MATCH($A30,$B$32:$Y$32,0)),">="&O$20)/ROWS($A$33:$A$242) -> 0.0047619048
A32: Hour | B32: 0 | C32: 1 | D32: 2 | E32: 3 | F32: 4 | G32: 5 | H32: 6 | I32: 7 | J32: 8 | K32: 9 | L32: 10 | M32: 11 | N32: 12 | O32: 13 | P32: 14 | Q32: 15 | R32: 16 | S32: 17 | T32: 18 | U32: 19 | V32: 20 | W32: 21 | X32: 22 | Y32: 23
A33: 43831 | B33: 21 | C33: 13 | D33: 5 | E33: 7 | F33: 3 | G33: 11 | H33: 6 | I33: 6 | J33: 11 | K33: 16 | L33: 15 | M33: 11 | N33: 15 | O33: 20 | P33: 18 | Q33: 17 | R33: 15 | S33: 22 | T33: 15 | U33: 19 | V33: 13 | W33: 17 | X33: 10 | Y33: 7
A34: 43832 | B34: 9 | C34: 2 | D34: 5 | E34: 6 | F34: 9 | G34: 8 | H34: 7 | I34: 11 | J34: 20 | K34: 29 | L34: 23 | M34: 29 | N34: 19 | O34: 19 | P34: 23 | Q34: 24 | R34: 32 | S34: 37 | T34: 20 | U34: 21 | V34: 15 | W34: 17 | X34: 12 | Y34: 18
A35: 43833 | B35: 7 | C35: 6 | D35: 4 | E35: 3 | F35: 13 | G35: 4 | H35: 24 | I35: 23 | J35: 24 | K35: 22 | L35: 20 | M35: 24 | N35: 19 | O35: 17 | P35: 20 | Q35: 21 | R35: 21 | S35: 41 | T35: 19 | U35: 20 | V35: 10 | W35: 9 | X35: 13 | Y35: 7
A36: 43834 | B36: 10 | C36: 9 | D36: 11 | E36: 20 | F36: 15 | G36: 12 | H36: 3 | I36: 12 | J36: 16 | K36: 17 | L36: 19 | M36: 19 | N36: 24 | O36: 29 | P36: 19 | Q36: 15 | R36: 18 | S36: 26 | T36: 29 | U36: 23 | V36: 10 | W36: 21 | X36: 11 | Y36: 14
A37: 43835 | B37: 9 | C37: 10 | D37: 9 | E37: 5 | F37: 2 | G37: 6 | H37: 7 | I37: 13 | J37: 13 | K37: 16 | L37: 17 | M37: 23 | N37: 10 | O37: 24 | P37: 16 | Q37: 10 | R37: 15 | S37: 15 | T37: 14 | U37: 18 | V37: 11 | W37: 6 | X37: 11 | Y37: 9
A38: 43836 | B38: 2 | C38: 6 | D38: 2 | E38: 9 | F38: 3 | G38: 9 | H38: 13 | I38: 17 | J38: 18 | K38: 18 | L38: 18 | M38: 22 | N38: 23 | O38: 14 | P38: 21 | Q38: 24 | R38: 25 | S38: 26 | T38: 13 | U38: 14 | V38: 20 | W38: 13 | X38: 15 | Y38: 8
A39: 43837 | B39: 4 | C39: 4 | D39: 6 | E39: 3 | F39: 6 | G39: 3 | H39: 10 | I39: 21 | J39: 28 | K39: 20 | L39: 27 | M39: 28 | N39: 14 | O39: 21 | P39: 18 | Q39: 15 | R39: 27 | S39: 36 | T39: 17 | U39: 19 | V39: 19 | W39: 10 | X39: 11 | Y39: 8
A40: 43838 | B40: 4 | C40: 8 | D40: 10 | E40: 9 | F40: 10 | G40: 10 | H40: 11 | I40: 16 | J40: 24 | K40: 25 | L40: 23 | M40: 25 | N40: 21 | O40: 20 | P40: 21 | Q40: 30 | R40: 32 | S40: 31 | T40: 24 | U40: 21 | V40: 19 | W40: 7 | X40: 2 | Y40: 9
A41: 43839 | B41: 8 | C41: 4 | D41: 3 | E41: 3 | F41: 4 | G41: 5 | H41: 6 | I41: 14 | J41: 35 | K41: 18 | L41: 17 | M41: 21 | N41: 25 | O41: 11 | P41: 22 | Q41: 23 | R41: 20 | S41: 30 | T41: 13 | U41: 19 | V41: 14 | W41: 11 | X41: 15 | Y41: 12
...

Sheet 2019
B1: NG_P(X≥3) | C1: Actual_P(X≥3) | D1: NG_P(X≥6) | E1: Actual_P(X≥6) | F1: NG_P(X≥9) | G1: Actual_P(X≥9) | H1: NG_P(X≥12) | I1: Actual_P(X≥12) | J1: NG_P(X≥15) | K1: Actual_P(X≥15)
A2: Low_frequency_hour | B2: 3 | C2: 3 | D2: 6 | E2: 6 | F2: 9 | G2: 9 | H2: 12 | I2: 12 | J2: 15 | K2: 15
A3: 0 | B3: =1-_xlfn.BETA.DIST(VLOOKUP($A3,NB_p!$A$2:$G$25,3,FALSE),VLOOKUP($A3,NB_r!$A$2:$G$25,3,FALSE),B$2,TRUE) -> 0.81271186 | C3: =COUNTIF(INDEX($B$33:$Y$397,0,MATCH($A3,$B$32:$Y$32,0)),">="&C$2)/ROWS($A$33:$A$397) -> 0.96986301 | D3: =1-_xlfn.BETA.DIST(VLOOKUP($A3,NB_p!$A$2:$G$25,3,FALSE),VLOOKUP($A3,NB_r!$A$2:$G$25,3,FALSE),D$2,TRUE) -> 0.59466883 | E3: =COUNTIF(INDEX($B$33:$Y$397,0,MATCH($A3,$B$32:$Y$32,0)),">="&E$2)/ROWS($A$33:$A$397) -> 0.76712329 | F3: =1-_xlfn.BETA.DIST(VLOOKUP($A3,NB_p!$A$2:$G$25,3,FALSE),VLOOKUP($A3,NB_r!$A$2:$G$25,3,FALSE),F$2,TRUE) -> 0.4148989 | G3: =COUNTIF(INDEX($B$33:$Y$397,0,MATCH($A3,$B$32:$Y$32,0)),">="&G$2)/ROWS($A$33:$A$397) -> 0.45479452 | H3: =1-_xlfn.BETA.DIST(VLOOKUP($A3,NB_p!$A$2:$G$25,3,FALSE),VLOOKUP($A3,NB_r!$A$2:$G$25,3,FALSE),H$2,TRUE) -> 0.28142587 | I3: =COUNTIF(INDEX($B$33:$Y$397,0,MATCH($A3,$B$32:$Y$32,0)),">="&I$2)/ROWS($A$33:$A$397) -> 0.20547945 | J3: =1-_xlfn.BETA.DIST(VLOOKUP($A3,NB_p!$A$2:$G$25,3,FALSE),VLOOKUP($A3,NB_r!$A$2:$G$25,3,FALSE),J$2,TRUE) -> 0.18732881 | K3: =COUNTIF(INDEX($B$33:$Y$397,0,MATCH($A3,$B$32:$Y$32,0)),">="&K$2)/ROWS($A$33:$A$397) -> 0.084931507
A4: 1 | B4: =1-_xlfn.BETA.DIST(VLOOKUP($A4,NB_p!$A$2:$G$25,3,FALSE),VLOOKUP($A4,NB_r!$A$2:$G$25,3,FALSE),B$2,TRUE) -> 0.84308208 | C4: =COUNTIF(INDEX($B$33:$Y$397,0,MATCH($A4,$B$32:$Y$32,0)),">="&C$2)/ROWS($A$33:$A$397) -> 0.96438356 | D4: =1-_xlfn.BETA.DIST(VLOOKUP($A4,NB_p!$A$2:$G$25,3,FALSE),VLOOKUP($A4,NB_r!$A$2:$G$25,3,FALSE),D$2,TRUE) -> 0.56896197 | E4: =COUNTIF(INDEX($B$33:$Y$397,0,MATCH($A4,$B$32:$Y$32,0)),">="&E$2)/ROWS($A$33:$A$397) -> 0.64657534 | F4: =1-_xlfn.BETA.DIST(VLOOKUP($A4,NB_p!$A$2:$G$25,3,FALSE),VLOOKUP($A4,NB_r!$A$2:$G$25,3,FALSE),F$2,TRUE) -> 0.33374107 | G4: =COUNTIF(INDEX($B$33:$Y$397,0,MATCH($A4,$B$32:$Y$32,0)),">="&G$2)/ROWS($A$33:$A$397) -> 0.27123288 | H4: =1-_xlfn.BETA.DIST(VLOOKUP($A4,NB_p!$A$2:$G$25,3,FALSE),VLOOKUP($A4,NB_r!$A$2:$G$25,3,FALSE),H$2,TRUE) -> 0.17886273 | I4: =COUNTIF(INDEX($B$33:$Y$397,0,MATCH($A4,$B$32:$Y$32,0)),">="&I$2)/ROWS($A$33:$A$397) -> 0.10410959 | J4: =1-_xlfn.BETA.DIST(VLOOKUP($A4,NB_p!$A$2:$G$25,3,FALSE),VLOOKUP($A4,NB_r!$A$2:$G$25,3,FALSE),J$2,TRUE) -> 0.090096919 | K4: =COUNTIF(INDEX($B$33:$Y$397,0,MATCH($A4,$B$32:$Y$32,0)),">="&K$2)/ROWS($A$33:$A$397) -> 0.035616438
A5: 2 | B5: =1-_xlfn.BETA.DIST(VLOOKUP($A5,NB_p!$A$2:$G$25,3,FALSE),VLOOKUP($A5,NB_r!$A$2:$G$25,3,FALSE),B$2,TRUE) -> 0.90663479 | C5: =COUNTIF(INDEX($B$33:$Y$397,0,MATCH($A5,$B$32:$Y$32,0)),">="&C$2)/ROWS($A$33:$A$397) -> 0.93150685 | D5: =1-_xlfn.BETA.DIST(VLOOKUP($A5,NB_p!$A$2:$G$25,3,FALSE),VLOOKUP($A5,NB_r!$A$2:$G$25,3,FALSE),D$2,TRUE) -> 0.57702077 | E5: =COUNTIF(INDEX($B$33:$Y$397,0,MATCH($A5,$B$32:$Y$32,0)),">="&E$2)/ROWS($A$33:$A$397) -> 0.56712329 | F5: =1-_xlfn.BETA.DIST(VLOOKUP($A5,NB_p!$A$2:$G$25,3,FALSE),VLOOKUP($A5,NB_r!$A$2:$G$25,3,FALSE),F$2,TRUE) -> 0.25075042 | G5: =COUNTIF(INDEX($B$33:$Y$397,0,MATCH($A5,$B$32:$Y$32,0)),">="&G$2)/ROWS($A$33:$A$397) -> 0.22191781 | H5: =1-_xlfn.BETA.DIST(VLOOKUP($A5,NB_p!$A$2:$G$25,3,FALSE),VLOOKUP($A5,NB_r!$A$2:$G$25,3,FALSE),H$2,TRUE) -> 0.080893896 | I5: =COUNTIF(INDEX($B$33:$Y$397,0,MATCH($A5,$B$32:$Y$32,0)),">="&I$2)/ROWS($A$33:$A$397) -> 0.076712329 | J5: =1-_xlfn.BETA.DIST(VLOOKUP($A5,NB_p!$A$2:$G$25,3,FALSE),VLOOKUP($A5,NB_r!$A$2:$G$25,3,FALSE),J$2,TRUE) -> 0.020905351 | K5: =COUNTIF(INDEX($B$33:$Y$397,0,MATCH($A5,$B$32:$Y$32,0)),">="&K$2)/ROWS($A$33:$A$397) -> 0.024657534
A6: 3 | B6: =1-_xlfn.BETA.DIST(VLOOKUP($A6,NB_p!$A$2:$G$25,3,FALSE),VLOOKUP($A6,NB_r!$A$2:$G$25,3,FALSE),B$2,TRUE) -> 0.88861999 | C6: =COUNTIF(INDEX($B$33:$Y$397,0,MATCH($A6,$B$32:$Y$32,0)),">="&C$2)/ROWS($A$33:$A$397) -> 0.89863014 | D6: =1-_xlfn.BETA.DIST(VLOOKUP($A6,NB_p!$A$2:$G$25,3,FALSE),VLOOKUP($A6,NB_r!$A$2:$G$25,3,FALSE),D$2,TRUE) -> 0.50059583 | E6: =COUNTIF(INDEX($B$33:$Y$397,0,MATCH($A6,$B$32:$Y$32,0)),">="&E$2)/ROWS($A$33:$A$397) -> 0.49315068 | F6: =1-_xlfn.BETA.DIST(VLOOKUP($A6,NB_p!$A$2:$G$25,3,FALSE),VLOOKUP($A6,NB_r!$A$2:$G$25,3,FALSE),F$2,TRUE) -> 0.1707594 | G6: =COUNTIF(INDEX($B$33:$Y$397,0,MATCH($A6,$B$32:$Y$32,0)),">="&G$2)/ROWS($A$33:$A$397) -> 0.17808219 | H6: =1-_xlfn.BETA.DIST(VLOOKUP($A6,NB_p!$A$2:$G$25,3,FALSE),VLOOKUP($A6,NB_r!$A$2:$G$25,3,FALSE),H$2,TRUE) -> 0.039295374 | I6: =COUNTIF(INDEX($B$33:$Y$397,0,MATCH($A6,$B$32:$Y$32,0)),">="&I$2)/ROWS($A$33:$A$397) -> 0.032876712 | J6: =1-_xlfn.BETA.DIST(VLOOKUP($A6,NB_p!$A$2:$G$25,3,FALSE),VLOOKUP($A6,NB_r!$A$2:$G$25,3,FALSE),J$2,TRUE) -> 0.0067339756 | K6: =COUNTIF(INDEX($B$33:$Y$397,0,MATCH($A6,$B$32:$Y$32,0)),">="&K$2)/ROWS($A$33:$A$397) -> 0.010958904
A7: 4 | B7: =1-_xlfn.BETA.DIST(VLOOKUP($A7,NB_p!$A$2:$G$25,3,FALSE),VLOOKUP($A7,NB_r!$A$2:$G$25,3,FALSE),B$2,TRUE) -> 0.82764131 | C7: =COUNTIF(INDEX($B$33:$Y$397,0,MATCH($A7,$B$32:$Y$32,0)),">="&C$2)/ROWS($A$33:$A$397) -> 0.88219178 | D7: =1-_xlfn.BETA.DIST(VLOOKUP($A7,NB_p!$A$2:$G$25,3,FALSE),VLOOKUP($A7,NB_r!$A$2:$G$25,3,FALSE),D$2,TRUE) -> 0.42842336 | E7: =COUNTIF(INDEX($B$33:$Y$397,0,MATCH($A7,$B$32:$Y$32,0)),">="&E$2)/ROWS($A$33:$A$397) -> 0.39178082 | F7: =1-_xlfn.BETA.DIST(VLOOKUP($A7,NB_p!$A$2:$G$25,3,FALSE),VLOOKUP($A7,NB_r!$A$2:$G$25,3,FALSE),F$2,TRUE) -> 0.14984663 | G7: =COUNTIF(INDEX($B$33:$Y$397,0,MATCH($A7,$B$32:$Y$32,0)),">="&G$2)/ROWS($A$33:$A$397) -> 0.12328767 | H7: =1-_xlfn.BETA.DIST(VLOOKUP($A7,NB_p!$A$2:$G$25,3,FALSE),VLOOKUP($A7,NB_r!$A$2:$G$25,3,FALSE),H$2,TRUE) -> 0.039904185 | I7: =COUNTIF(INDEX($B$33:$Y$397,0,MATCH($A7,$B$32:$Y$32,0)),">="&I$2)/ROWS($A$33:$A$397) -> 0.035616438 | J7: =1-_xlfn.BETA.DIST(VLOOKUP($A7,NB_p!$A$2:$G$25,3,FALSE),VLOOKUP($A7,NB_r!$A$2:$G$25,3,FALSE),J$2,TRUE) -> 0.0087696719 | K7: =COUNTIF(INDEX($B$33:$Y$397,0,MATCH($A7,$B$32:$Y$32,0)),">="&K$2)/ROWS($A$33:$A$397) -> 0.021917808
A8: 5 | B8: =1-_xlfn.BETA.DIST(VLOOKUP($A8,NB_p!$A$2:$G$25,3,FALSE),VLOOKUP($A8,NB_r!$A$2:$G$25,3,FALSE),B$2,TRUE) -> 0.90693989 | C8: =COUNTIF(INDEX($B$33:$Y$397,0,MATCH($A8,$B$32:$Y$32,0)),">="&C$2)/ROWS($A$33:$A$397) -> 0.95616438 | D8: =1-_xlfn.BETA.DIST(VLOOKUP($A8,NB_p!$A$2:$G$25,3,FALSE),VLOOKUP($A8,NB_r!$A$2:$G$25,3,FALSE),D$2,TRUE) -> 0.62937517 | E8: =COUNTIF(INDEX($B$33:$Y$397,0,MATCH($A8,$B$32:$Y$32,0)),">="&E$2)/ROWS($A$33:$A$397) -> 0.63013699 | F8: =1-_xlfn.BETA.DIST(VLOOKUP($A8,NB_p!$A$2:$G$25,3,FALSE),VLOOKUP($A8,NB_r!$A$2:$G$25,3,FALSE),F$2,TRUE) -> 0.33984894 | G8: =COUNTIF(INDEX($B$33:$Y$397,0,MATCH($A8,$B$32:$Y$32,0)),">="&G$2)/ROWS($A$33:$A$397) -> 0.30136986 | H8: =1-_xlfn.BETA.DIST(VLOOKUP($A8,NB_p!$A$2:$G$25,3,FALSE),VLOOKUP($A8,NB_r!$A$2:$G$25,3,FALSE),H$2,TRUE) -> 0.15224974 | I8: =COUNTIF(INDEX($B$33:$Y$397,0,MATCH($A8,$B$32:$Y$32,0)),">="&I$2)/ROWS($A$33:$A$397) -> 0.12328767 | J8: =1-_xlfn.BETA.DIST(VLOOKUP($A8,NB_p!$A$2:$G$25,3,FALSE),VLOOKUP($A8,NB_r!$A$2:$G$25,3,FALSE),J$2,TRUE) -> 0.059514511 | K8: =COUNTIF(INDEX($B$33:$Y$397,0,MATCH($A8,$B$32:$Y$32,0)),">="&K$2)/ROWS($A$33:$A$397) -> 0.04109589
A9: 6 | B9: =1-_xlfn.BETA.DIST(VLOOKUP($A9,NB_p!$A$2:$G$25,3,FALSE),VLOOKUP($A9,NB_r!$A$2:$G$25,3,FALSE),B$2,TRUE) -> 0.96647202 | C9: =COUNTIF(INDEX($B$33:$Y$397,0,MATCH($A9,$B$32:$Y$32,0)),">="&C$2)/ROWS($A$33:$A$397) -> 0.97534247 | D9: =1-_xlfn.BETA.DIST(VLOOKUP($A9,NB_p!$A$2:$G$25,3,FALSE),VLOOKUP($A9,NB_r!$A$2:$G$25,3,FALSE),D$2,TRUE) -> 0.82299944 | E9: =COUNTIF(INDEX($B$33:$Y$397,0,MATCH($A9,$B$32:$Y$32,0)),">="&E$2)/ROWS($A$33:$A$397) -> 0.85753425 | F9: =1-_xlfn.BETA.DIST(VLOOKUP($A9,NB_p!$A$2:$G$25,3,FALSE),VLOOKUP($A9,NB_r!$A$2:$G$25,3,FALSE),F$2,TRUE) -> 0.60006957 | G9: =COUNTIF(INDEX($B$33:$Y$397,0,MATCH($A9,$B$32:$Y$32,0)),">="&G$2)/ROWS($A$33:$A$397) -> 0.6 | H9: =1-_xlfn.BETA.DIST(VLOOKUP($A9,NB_p!$A$2:$G$25,3,FALSE),VLOOKUP($A9,NB_r!$A$2:$G$25,3,FALSE),H$2,TRUE) -> 0.38195943 | I9: =COUNTIF(INDEX($B$33:$Y$397,0,MATCH($A9,$B$32:$Y$32,0)),">="&I$2)/ROWS($A$33:$A$397) -> 0.35342466 | J9: =1-_xlfn.BETA.DIST(VLOOKUP($A9,NB_p!$A$2:$G$25,3,FALSE),VLOOKUP($A9,NB_r!$A$2:$G$25,3,FALSE),J$2,TRUE) -> 0.2180907 | K9: =COUNTIF(INDEX($B$33:$Y$397,0,MATCH($A9,$B$32:$Y$32,0)),">="&K$2)/ROWS($A$33:$A$397) -> 0.19178082
A10: 23 | B10: =1-_xlfn.BETA.DIST(VLOOKUP($A10,NB_p!$A$2:$G$25,3,FALSE),VLOOKUP($A10,NB_r!$A$2:$G$25,3,FALSE),B$2,TRUE) -> 0.9673783 | C10: =COUNTIF(INDEX($B$33:$Y$397,0,MATCH($A10,$B$32:$Y$32,0)),">="&C$2)/ROWS($A$33:$A$397) -> 0.98630137 | D10: =1-_xlfn.BETA.DIST(VLOOKUP($A10,NB_p!$A$2:$G$25,3,FALSE),VLOOKUP($A10,NB_r!$A$2:$G$25,3,FALSE),D$2,TRUE) -> 0.82087515 | E10: =COUNTIF(INDEX($B$33:$Y$397,0,MATCH($A10,$B$32:$Y$32,0)),">="&E$2)/ROWS($A$33:$A$397) -> 0.88493151 | F10: =1-_xlfn.BETA.DIST(VLOOKUP($A10,NB_p!$A$2:$G$25,3,FALSE),VLOOKUP($A10,NB_r!$A$2:$G$25,3,FALSE),F$2,TRUE) -> 0.58980148 | G10: =COUNTIF(INDEX($B$33:$Y$397,0,MATCH($A10,$B$32:$Y$32,0)),">="&G$2)/ROWS($A$33:$A$397) -> 0.61917808 | H10: =1-_xlfn.BETA.DIST(VLOOKUP($A10,NB_p!$A$2:$G$25,3,FALSE),VLOOKUP($A10,NB_r!$A$2:$G$25,3,FALSE),H$2,TRUE) -> 0.36566748 | I10: =COUNTIF(INDEX($B$33:$Y$397,0,MATCH($A10,$B$32:$Y$32,0)),">="&I$2)/ROWS($A$33:$A$397) -> 0.33150685 | J10: =1-_xlfn.BETA.DIST(VLOOKUP($A10,NB_p!$A$2:$G$25,3,FALSE),VLOOKUP($A10,NB_r!$A$2:$G$25,3,FALSE),J$2,TRUE) -> 0.20137221 | K10: =COUNTIF(INDEX($B$33:$Y$397,0,MATCH($A10,$B$32:$Y$32,0)),">="&K$2)/ROWS($A$33:$A$397) -> 0.1260274
B11: NG_P(X≥5) | C11: Actual_P(X≥5) | D11: NG_P(X≥10) | E11: Actual_P(X≥10) | F11: NG_P(X≥15) | G11: Actual_P(X≥15) | H11: NG_P(X≥20) | I11: Actual_P(X≥20) | J11: NG_P(X≥25) | K11: Actual_P(X≥25) | L11: NG_P(X≥30) | M11: Actual_P(X≥30)
A12: Mid_frequency_hour | B12: 5 | C12: 5 | D12: 10 | E12: 10 | F12: 15 | G12: 15 | H12: 20 | I12: 20 | J12: 25 | K12: 25 | L12: 30 | M12: 30
A13: 7 | B13: =1-_xlfn.BETA.DIST(VLOOKUP($A13,NB_p!$A$2:$G$25,3,FALSE),VLOOKUP($A13,NB_r!$A$2:$G$25,3,FALSE),B$12,TRUE) -> 0.97729866 | C13: =COUNTIF(INDEX($B$33:$Y$397,0,MATCH($A13,$B$32:$Y$32,0)),">="&C$12)/ROWS($A$33:$A$397) -> 0.98082192 | D13: =1-_xlfn.BETA.DIST(VLOOKUP($A13,NB_p!$A$2:$G$25,3,FALSE),VLOOKUP($A13,NB_r!$A$2:$G$25,3,FALSE),D$12,TRUE) -> 0.8284371 | E13: =COUNTIF(INDEX($B$33:$Y$397,0,MATCH($A13,$B$32:$Y$32,0)),">="&E$12)/ROWS($A$33:$A$397) -> 0.81643836 | F13: =1-_xlfn.BETA.DIST(VLOOKUP($A13,NB_p!$A$2:$G$25,3,FALSE),VLOOKUP($A13,NB_r!$A$2:$G$25,3,FALSE),F$12,TRUE) -> 0.56822563 | G13: =COUNTIF(INDEX($B$33:$Y$397,0,MATCH($A13,$B$32:$Y$32,0)),">="&G$12)/ROWS($A$33:$A$397) -> 0.5890411 | H13: =1-_xlfn.BETA.DIST(VLOOKUP($A13,NB_p!$A$2:$G$25,3,FALSE),VLOOKUP($A13,NB_r!$A$2:$G$25,3,FALSE),H$12,TRUE) -> 0.32169613 | I13: =COUNTIF(INDEX($B$33:$Y$397,0,MATCH($A13,$B$32:$Y$32,0)),">="&I$12)/ROWS($A$33:$A$397) -> 0.33972603 | J13: =1-_xlfn.BETA.DIST(VLOOKUP($A13,NB_p!$A$2:$G$25,3,FALSE),VLOOKUP($A13,NB_r!$A$2:$G$25,3,FALSE),J$12,TRUE) -> 0.15642638 | K13: =COUNTIF(INDEX($B$33:$Y$397,0,MATCH($A13,$B$32:$Y$32,0)),">="&K$12)/ROWS($A$33:$A$397) -> 0.14794521 | L13: =1-_xlfn.BETA.DIST(VLOOKUP($A13,NB_p!$A$2:$G$25,3,FALSE),VLOOKUP($A13,NB_r!$A$2:$G$25,3,FALSE),L$12,TRUE) -> 0.067600363 | M13: =COUNTIF(INDEX($B$33:$Y$397,0,MATCH($A13,$B$32:$Y$32,0)),">="&M$12)/ROWS($A$33:$A$397) -> 0.046575342
A14: 8 | B14: =1-_xlfn.BETA.DIST(VLOOKUP($A14,NB_p!$A$2:$G$25,3,FALSE),VLOOKUP($A14,NB_r!$A$2:$G$25,3,FALSE),B$12,TRUE) -> 0.99745639 | C14: =COUNTIF(INDEX($B$33:$Y$397,0,MATCH($A14,$B$32:$Y$32,0)),">="&C$12)/ROWS($A$33:$A$397) -> 0.99726027 | D14: =1-_xlfn.BETA.DIST(VLOOKUP($A14,NB_p!$A$2:$G$25,3,FALSE),VLOOKUP($A14,NB_r!$A$2:$G$25,3,FALSE),D$12,TRUE) -> 0.9517172 | E14: =COUNTIF(INDEX($B$33:$Y$397,0,MATCH($A14,$B$32:$Y$32,0)),">="&E$12)/ROWS($A$33:$A$397) -> 0.9369863 | F14: =1-_xlfn.BETA.DIST(VLOOKUP($A14,NB_p!$A$2:$G$25,3,FALSE),VLOOKUP($A14,NB_r!$A$2:$G$25,3,FALSE),F$12,TRUE) -> 0.7881128 | G14: =COUNTIF(INDEX($B$33:$Y$397,0,MATCH($A14,$B$32:$Y$32,0)),">="&G$12)/ROWS($A$33:$A$397) -> 0.79726027 | H14: =1-_xlfn.BETA.DIST(VLOOKUP($A14,NB_p!$A$2:$G$25,3,FALSE),VLOOKUP($A14,NB_r!$A$2:$G$25,3,FALSE),H$12,TRUE) -> 0.53422283 | I14: =COUNTIF(INDEX($B$33:$Y$397,0,MATCH($A14,$B$32:$Y$32,0)),">="&I$12)/ROWS($A$33:$A$397) -> 0.5369863 | J14: =1-_xlfn.BETA.DIST(VLOOKUP($A14,NB_p!$A$2:$G$25,3,FALSE),VLOOKUP($A14,NB_r!$A$2:$G$25,3,FALSE),J$12,TRUE) -> 0.29695745 | K14: =COUNTIF(INDEX($B$33:$Y$397,0,MATCH($A14,$B$32:$Y$32,0)),">="&K$12)/ROWS($A$33:$A$397) -> 0.30136986 | L14: =1-_xlfn.BETA.DIST(VLOOKUP($A14,NB_p!$A$2:$G$25,3,FALSE),VLOOKUP($A14,NB_r!$A$2:$G$25,3,FALSE),L$12,TRUE) -> 0.13895802 | M14: =COUNTIF(INDEX($B$33:$Y$397,0,MATCH($A14,$B$32:$Y$32,0)),">="&M$12)/ROWS($A$33:$A$397) -> 0.1369863
A15: 19 | B15: =1-_xlfn.BETA.DIST(VLOOKUP($A15,NB_p!$A$2:$G$25,3,FALSE),VLOOKUP($A15,NB_r!$A$2:$G$25,3,FALSE),B$12,TRUE) -> 0.9963591 | C15: =COUNTIF(INDEX($B$33:$Y$397,0,MATCH($A15,$B$32:$Y$32,0)),">="&C$12)/ROWS($A$33:$A$397) -> 1 | D15: =1-_xlfn.BETA.DIST(VLOOKUP($A15,NB_p!$A$2:$G$25,3,FALSE),VLOOKUP($A15,NB_r!$A$2:$G$25,3,FALSE),D$12,TRUE) -> 0.94030826 | E15: =COUNTIF(INDEX($B$33:$Y$397,0,MATCH($A15,$B$32:$Y$32,0)),">="&E$12)/ROWS($A$33:$A$397) -> 0.98356164 | F15: =1-_xlfn.BETA.DIST(VLOOKUP($A15,NB_p!$A$2:$G$25,3,FALSE),VLOOKUP($A15,NB_r!$A$2:$G$25,3,FALSE),F$12,TRUE) -> 0.7608994 | G15: =COUNTIF(INDEX($B$33:$Y$397,0,MATCH($A15,$B$32:$Y$32,0)),">="&G$12)/ROWS($A$33:$A$397) -> 0.82739726 | H15: =1-_xlfn.BETA.DIST(VLOOKUP($A15,NB_p!$A$2:$G$25,3,FALSE),VLOOKUP($A15,NB_r!$A$2:$G$25,3,FALSE),H$12,TRUE) -> 0.50323109 | I15: =COUNTIF(INDEX($B$33:$Y$397,0,MATCH($A15,$B$32:$Y$32,0)),">="&I$12)/ROWS($A$33:$A$397) -> 0.49863014 | J15: =1-_xlfn.BETA.DIST(VLOOKUP($A15,NB_p!$A$2:$G$25,3,FALSE),VLOOKUP($A15,NB_r!$A$2:$G$25,3,FALSE),J$12,TRUE) -> 0.27460739 | K15: =COUNTIF(INDEX($B$33:$Y$397,0,MATCH($A15,$B$32:$Y$32,0)),">="&K$12)/ROWS($A$33:$A$397) -> 0.19726027 | L15: =1-_xlfn.BETA.DIST(VLOOKUP($A15,NB_p!$A$2:$G$25,3,FALSE),VLOOKUP($A15,NB_r!$A$2:$G$25,3,FALSE),L$12,TRUE) -> 0.1272346 | M15: =COUNTIF(INDEX($B$33:$Y$397,0,MATCH($A15,$B$32:$Y$32,0)),">="&M$12)/ROWS($A$33:$A$397) -> 0.065753425
A16: 20 | B16: =1-_xlfn.BETA.DIST(VLOOKUP($A16,NB_p!$A$2:$G$25,3,FALSE),VLOOKUP($A16,NB_r!$A$2:$G$25,3,FALSE),B$12,TRUE) -> 0.99334396 | C16: =COUNTIF(INDEX($B$33:$Y$397,0,MATCH($A16,$B$32:$Y$32,0)),">="&C$12)/ROWS($A$33:$A$397) -> 0.99726027 | D16: =1-_xlfn.BETA.DIST(VLOOKUP($A16,NB_p!$A$2:$G$25,3,FALSE),VLOOKUP($A16,NB_r!$A$2:$G$25,3,FALSE),D$12,TRUE) -> 0.8983416 | E16: =COUNTIF(INDEX($B$33:$Y$397,0,MATCH($A16,$B$32:$Y$32,0)),">="&E$12)/ROWS($A$33:$A$397) -> 0.9369863 | F16: =1-_xlfn.BETA.DIST(VLOOKUP($A16,NB_p!$A$2:$G$25,3,FALSE),VLOOKUP($A16,NB_r!$A$2:$G$25,3,FALSE),F$12,TRUE) -> 0.63980408 | G16: =COUNTIF(INDEX($B$33:$Y$397,0,MATCH($A16,$B$32:$Y$32,0)),">="&G$12)/ROWS($A$33:$A$397) -> 0.64109589 | H16: =1-_xlfn.BETA.DIST(VLOOKUP($A16,NB_p!$A$2:$G$25,3,FALSE),VLOOKUP($A16,NB_r!$A$2:$G$25,3,FALSE),H$12,TRUE) -> 0.34387371 | I16: =COUNTIF(INDEX($B$33:$Y$397,0,MATCH($A16,$B$32:$Y$32,0)),">="&I$12)/ROWS($A$33:$A$397) -> 0.32328767 | J16: =1-_xlfn.BETA.DIST(VLOOKUP($A16,NB_p!$A$2:$G$25,3,FALSE),VLOOKUP($A16,NB_r!$A$2:$G$25,3,FALSE),J$12,TRUE) -> 0.14404926 | K16: =COUNTIF(INDEX($B$33:$Y$397,0,MATCH($A16,$B$32:$Y$32,0)),">="&K$12)/ROWS($A$33:$A$397) -> 0.098630137 | L16: =1-_xlfn.BETA.DIST(VLOOKUP($A16,NB_p!$A$2:$G$25,3,FALSE),VLOOKUP($A16,NB_r!$A$2:$G$25,3,FALSE),L$12,TRUE) -> 0.049258784 | M16: =COUNTIF(INDEX($B$33:$Y$397,0,MATCH($A16,$B$32:$Y$32,0)),">="&M$12)/ROWS($A$33:$A$397) -> 0.038356164
A17: 21 | B17: =1-_xlfn.BETA.DIST(VLOOKUP($A17,NB_p!$A$2:$G$25,3,FALSE),VLOOKUP($A17,NB_r!$A$2:$G$25,3,FALSE),B$12,TRUE) -> 0.98805843 | C17: =COUNTIF(INDEX($B$33:$Y$397,0,MATCH($A17,$B$32:$Y$32,0)),">="&C$12)/ROWS($A$33:$A$397) -> 0.99726027 | D17: =1-_xlfn.BETA.DIST(VLOOKUP($A17,NB_p!$A$2:$G$25,3,FALSE),VLOOKUP($A17,NB_r!$A$2:$G$25,3,FALSE),D$12,TRUE) -> 0.84326294 | E17: =COUNTIF(INDEX($B$33:$Y$397,0,MATCH($A17,$B$32:$Y$32,0)),">="&E$12)/ROWS($A$33:$A$397) -> 0.87671233 | F17: =1-_xlfn.BETA.DIST(VLOOKUP($A17,NB_p!$A$2:$G$25,3,FALSE),VLOOKUP($A17,NB_r!$A$2:$G$25,3,FALSE),F$12,TRUE) -> 0.5214134 | G17: =COUNTIF(INDEX($B$33:$Y$397,0,MATCH($A17,$B$32:$Y$32,0)),">="&G$12)/ROWS($A$33:$A$397) -> 0.51506849 | H17: =1-_xlfn.BETA.DIST(VLOOKUP($A17,NB_p!$A$2:$G$25,3,FALSE),VLOOKUP($A17,NB_r!$A$2:$G$25,3,FALSE),H$12,TRUE) -> 0.22922529 | I17: =COUNTIF(INDEX($B$33:$Y$397,0,MATCH($A17,$B$32:$Y$32,0)),">="&I$12)/ROWS($A$33:$A$397) -> 0.19726027 | J17: =1-_xlfn.BETA.DIST(VLOOKUP($A17,NB_p!$A$2:$G$25,3,FALSE),VLOOKUP($A17,NB_r!$A$2:$G$25,3,FALSE),J$12,TRUE) -> 0.075832898 | K17: =COUNTIF(INDEX($B$33:$Y$397,0,MATCH($A17,$B$32:$Y$32,0)),">="&K$12)/ROWS($A$33:$A$397) -> 0.052054795 | L17: =1-_xlfn.BETA.DIST(VLOOKUP($A17,NB_p!$A$2:$G$25,3,FALSE),VLOOKUP($A17,NB_r!$A$2:$G$25,3,FALSE),L$12,TRUE) -> 0.02004681 | M17: =COUNTIF(INDEX($B$33:$Y$397,0,MATCH($A17,$B$32:$Y$32,0)),">="&M$12)/ROWS($A$33:$A$397) -> 0.019178082
A18: 22 | B18: =1-_xlfn.BETA.DIST(VLOOKUP($A18,NB_p!$A$2:$G$25,3,FALSE),VLOOKUP($A18,NB_r!$A$2:$G$25,3,FALSE),B$12,TRUE) -> 0.97066168 | C18: =COUNTIF(INDEX($B$33:$Y$397,0,MATCH($A18,$B$32:$Y$32,0)),">="&C$12)/ROWS($A$33:$A$397) -> 0.9890411 | D18: =1-_xlfn.BETA.DIST(VLOOKUP($A18,NB_p!$A$2:$G$25,3,FALSE),VLOOKUP($A18,NB_r!$A$2:$G$25,3,FALSE),D$12,TRUE) -> 0.69831467 | E18: =COUNTIF(INDEX($B$33:$Y$397,0,MATCH($A18,$B$32:$Y$32,0)),">="&E$12)/ROWS($A$33:$A$397) -> 0.70958904 | F18: =1-_xlfn.BETA.DIST(VLOOKUP($A18,NB_p!$A$2:$G$25,3,FALSE),VLOOKUP($A18,NB_r!$A$2:$G$25,3,FALSE),F$12,TRUE) -> 0.2949996 | G18: =COUNTIF(INDEX($B$33:$Y$397,0,MATCH($A18,$B$32:$Y$32,0)),">="&G$12)/ROWS($A$33:$A$397) -> 0.2739726 | H18: =1-_xlfn.BETA.DIST(VLOOKUP($A18,NB_p!$A$2:$G$25,3,FALSE),VLOOKUP($A18,NB_r!$A$2:$G$25,3,FALSE),H$12,TRUE) -> 0.076741505 | I18: =COUNTIF(INDEX($B$33:$Y$397,0,MATCH($A18,$B$32:$Y$32,0)),">="&I$12)/ROWS($A$33:$A$397) -> 0.082191781 | J18: =1-_xlfn.BETA.DIST(VLOOKUP($A18,NB_p!$A$2:$G$25,3,FALSE),VLOOKUP($A18,NB_r!$A$2:$G$25,3,FALSE),J$12,TRUE) -> 0.013728002 | K18: =COUNTIF(INDEX($B$33:$Y$397,0,MATCH($A18,$B$32:$Y$32,0)),">="&K$12)/ROWS($A$33:$A$397) -> 0.016438356 | L18: =1-_xlfn.BETA.DIST(VLOOKUP($A18,NB_p!$A$2:$G$25,3,FALSE),VLOOKUP($A18,NB_r!$A$2:$G$25,3,FALSE),L$12,TRUE) -> 0.0018472683 | M18: =COUNTIF(INDEX($B$33:$Y$397,0,MATCH($A18,$B$32:$Y$32,0)),">="&M$12)/ROWS($A$33:$A$397) -> 0.0082191781
B19: NG_P(X≥10) | C19: Actual_P(X≥10) | D19: NG_P(X≥15) | E19: Actual_P(X≥15) | F19: NG_P(X≥20) | G19: Actual_P(X≥20) | H19: NG_P(X≥25) | I19: Actual_P(X≥25) | J19: NG_P(X≥30) | K19: Actual_P(X≥30) | L19: NG_P(X≥35) | M19: Actual_P(X≥35) | N19: NG_P(X≥40) | O19: Actual_P(X≥40)
A20: High_frequency_hour | B20: 10 | C20: 10 | D20: 15 | E20: 15 | F20: 20 | G20: 20 | H20: 25 | I20: 25 | J20: 30 | K20: 30 | L20: 35 | M20: 35 | N20: 40 | O20: 40
A21: 9 | B21: =1-_xlfn.BETA.DIST(VLOOKUP($A21,NB_p!$A$2:$G$25,3,FALSE),VLOOKUP($A21,NB_r!$A$2:$G$25,3,FALSE),B$20,TRUE) -> 0.97283656 | C21: =COUNTIF(INDEX($B$33:$Y$397,0,MATCH($A21,$B$32:$Y$32,0)),">="&C$20)/ROWS($A$33:$A$397) -> 0.97808219 | D21: =1-_xlfn.BETA.DIST(VLOOKUP($A21,NB_p!$A$2:$G$25,3,FALSE),VLOOKUP($A21,NB_r!$A$2:$G$25,3,FALSE),D$20,TRUE) -> 0.8490074 | E21: =COUNTIF(INDEX($B$33:$Y$397,0,MATCH($A21,$B$32:$Y$32,0)),">="&E$20)/ROWS($A$33:$A$397) -> 0.85205479 | F21: =1-_xlfn.BETA.DIST(VLOOKUP($A21,NB_p!$A$2:$G$25,3,FALSE),VLOOKUP($A21,NB_r!$A$2:$G$25,3,FALSE),F$20,TRUE) -> 0.61376104 | G21: =COUNTIF(INDEX($B$33:$Y$397,0,MATCH($A21,$B$32:$Y$32,0)),">="&G$20)/ROWS($A$33:$A$397) -> 0.64657534 | H21: =1-_xlfn.BETA.DIST(VLOOKUP($A21,NB_p!$A$2:$G$25,3,FALSE),VLOOKUP($A21,NB_r!$A$2:$G$25,3,FALSE),H$20,TRUE) -> 0.36042121 | I21: =COUNTIF(INDEX($B$33:$Y$397,0,MATCH($A21,$B$32:$Y$32,0)),">="&I$20)/ROWS($A$33:$A$397) -> 0.34520548 | J21: =1-_xlfn.BETA.DIST(VLOOKUP($A21,NB_p!$A$2:$G$25,3,FALSE),VLOOKUP($A21,NB_r!$A$2:$G$25,3,FALSE),J$20,TRUE) -> 0.1749057 | K21: =COUNTIF(INDEX($B$33:$Y$397,0,MATCH($A21,$B$32:$Y$32,0)),">="&K$20)/ROWS($A$33:$A$397) -> 0.14794521 | L21: =1-_xlfn.BETA.DIST(VLOOKUP($A21,NB_p!$A$2:$G$25,3,FALSE),VLOOKUP($A21,NB_r!$A$2:$G$25,3,FALSE),L$20,TRUE) -> 0.072078014 | M21: =COUNTIF(INDEX($B$33:$Y$397,0,MATCH($A21,$B$32:$Y$32,0)),">="&M$20)/ROWS($A$33:$A$397) -> 0.057534247 | N21: =1-_xlfn.BETA.DIST(VLOOKUP($A21,NB_p!$A$2:$G$25,3,FALSE),VLOOKUP($A21,NB_r!$A$2:$G$25,3,FALSE),N$20,TRUE) -> 0.025890662 | O21: =COUNTIF(INDEX($B$33:$Y$397,0,MATCH($A21,$B$32:$Y$32,0)),">="&O$20)/ROWS($A$33:$A$397) -> 0.010958904
A22: 10 | B22: =1-_xlfn.BETA.DIST(VLOOKUP($A22,NB_p!$A$2:$G$25,3,FALSE),VLOOKUP($A22,NB_r!$A$2:$G$25,3,FALSE),B$20,TRUE) -> 0.98957005 | C22: =COUNTIF(INDEX($B$33:$Y$397,0,MATCH($A22,$B$32:$Y$32,0)),">="&C$20)/ROWS($A$33:$A$397) -> 0.98356164 | D22: =1-_xlfn.BETA.DIST(VLOOKUP($A22,NB_p!$A$2:$G$25,3,FALSE),VLOOKUP($A22,NB_r!$A$2:$G$25,3,FALSE),D$20,TRUE) -> 0.89826301 | E22: =COUNTIF(INDEX($B$33:$Y$397,0,MATCH($A22,$B$32:$Y$32,0)),">="&E$20)/ROWS($A$33:$A$397) -> 0.90684932 | F22: =1-_xlfn.BETA.DIST(VLOOKUP($A22,NB_p!$A$2:$G$25,3,FALSE),VLOOKUP($A22,NB_r!$A$2:$G$25,3,FALSE),F$20,TRUE) -> 0.65053611 | G22: =COUNTIF(INDEX($B$33:$Y$397,0,MATCH($A22,$B$32:$Y$32,0)),">="&G$20)/ROWS($A$33:$A$397) -> 0.69589041 | H22: =1-_xlfn.BETA.DIST(VLOOKUP($A22,NB_p!$A$2:$G$25,3,FALSE),VLOOKUP($A22,NB_r!$A$2:$G$25,3,FALSE),H$20,TRUE) -> 0.34634198 | I22: =COUNTIF(INDEX($B$33:$Y$397,0,MATCH($A22,$B$32:$Y$32,0)),">="&I$20)/ROWS($A$33:$A$397) -> 0.32054795 | J22: =1-_xlfn.BETA.DIST(VLOOKUP($A22,NB_p!$A$2:$G$25,3,FALSE),VLOOKUP($A22,NB_r!$A$2:$G$25,3,FALSE),J$20,TRUE) -> 0.1352424 | K22: =COUNTIF(INDEX($B$33:$Y$397,0,MATCH($A22,$B$32:$Y$32,0)),">="&K$20)/ROWS($A$33:$A$397) -> 0.11232877 | L22: =1-_xlfn.BETA.DIST(VLOOKUP($A22,NB_p!$A$2:$G$25,3,FALSE),VLOOKUP($A22,NB_r!$A$2:$G$25,3,FALSE),L$20,TRUE) -> 0.040008316 | M22: =COUNTIF(INDEX($B$33:$Y$397,0,MATCH($A22,$B$32:$Y$32,0)),">="&M$20)/ROWS($A$33:$A$397) -> 0.032876712 | N22: =1-_xlfn.BETA.DIST(VLOOKUP($A22,NB_p!$A$2:$G$25,3,FALSE),VLOOKUP($A22,NB_r!$A$2:$G$25,3,FALSE),N$20,TRUE) -> 0.0093195626 | O22: =COUNTIF(INDEX($B$33:$Y$397,0,MATCH($A22,$B$32:$Y$32,0)),">="&O$20)/ROWS($A$33:$A$397) -> 0.01369863
